[2020-01-14 01:22:18 +0000] [7] [INFO] Starting gunicorn 20.0.4
[2020-01-14 01:22:18 +0000] [7] [INFO] Listening at: http://0.0.0.0:8888 (7)
[2020-01-14 01:22:18 +0000] [7] [INFO] Using worker: gevent
[2020-01-14 01:22:18 +0000] [10] [INFO] Booting worker with pid: 10
[2020-01-14 01:22:18 +0000] [11] [INFO] Booting worker with pid: 11
[2020-02-01 17:35:20 +0000] [10] [INFO] Starting gunicorn 20.0.4
[2020-02-01 17:35:20 +0000] [10] [INFO] Listening at: http://0.0.0.0:8888 (10)
[2020-02-01 17:35:20 +0000] [10] [INFO] Using worker: gevent
[2020-02-01 17:35:20 +0000] [13] [INFO] Booting worker with pid: 13
[2020-02-01 17:35:20 +0000] [14] [INFO] Booting worker with pid: 14
[2020-02-01 17:35:21 +0000] [13] [ERROR] Exception in worker process
Traceback (most recent call last):
  File "/usr/local/lib/python3.6/site-packages/gunicorn/arbiter.py", line 583, in spawn_worker
    worker.init_process()
  File "/usr/local/lib/python3.6/site-packages/gunicorn/workers/ggevent.py", line 162, in init_process
    super().init_process()
  File "/usr/local/lib/python3.6/site-packages/gunicorn/workers/base.py", line 119, in init_process
    self.load_wsgi()
  File "/usr/local/lib/python3.6/site-packages/gunicorn/workers/base.py", line 144, in load_wsgi
    self.wsgi = self.app.wsgi()
  File "/usr/local/lib/python3.6/site-packages/gunicorn/app/base.py", line 67, in wsgi
    self.callable = self.load()
  File "/usr/local/lib/python3.6/site-packages/gunicorn/app/wsgiapp.py", line 49, in load
    return self.load_wsgiapp()
  File "/usr/local/lib/python3.6/site-packages/gunicorn/app/wsgiapp.py", line 39, in load_wsgiapp
    return util.import_app(self.app_uri)
  File "/usr/local/lib/python3.6/site-packages/gunicorn/util.py", line 358, in import_app
    mod = importlib.import_module(module)
  File "/usr/local/lib/python3.6/importlib/__init__.py", line 126, in import_module
    return _bootstrap._gcd_import(name[level:], package, level)
  File "<frozen importlib._bootstrap>", line 994, in _gcd_import
  File "<frozen importlib._bootstrap>", line 971, in _find_and_load
  File "<frozen importlib._bootstrap>", line 955, in _find_and_load_unlocked
  File "<frozen importlib._bootstrap>", line 665, in _load_unlocked
  File "<frozen importlib._bootstrap_external>", line 678, in exec_module
  File "<frozen importlib._bootstrap>", line 219, in _call_with_frames_removed
  File "/app/app/app.py", line 6, in <module>
    from search import get_similar_tovar
  File "/app/app/search.py", line 14, in <module>
    data = pd.read_excel('../test_data/data.xlsx')
  File "/usr/local/lib/python3.6/site-packages/pandas/io/excel/_base.py", line 304, in read_excel
    io = ExcelFile(io, engine=engine)
  File "/usr/local/lib/python3.6/site-packages/pandas/io/excel/_base.py", line 821, in __init__
    self._reader = self._engines[engine](self._io)
  File "/usr/local/lib/python3.6/site-packages/pandas/io/excel/_xlrd.py", line 20, in __init__
    import_optional_dependency("xlrd", extra=err_msg)
  File "/usr/local/lib/python3.6/site-packages/pandas/compat/_optional.py", line 92, in import_optional_dependency
    raise ImportError(msg) from None
ImportError: Missing optional dependency 'xlrd'. Install xlrd >= 1.0.0 for Excel support Use pip or conda to install xlrd.
[2020-02-01 17:35:21 +0000] [13] [INFO] Worker exiting (pid: 13)
[2020-02-01 17:35:21 +0000] [14] [ERROR] Exception in worker process
Traceback (most recent call last):
  File "/usr/local/lib/python3.6/site-packages/gunicorn/arbiter.py", line 583, in spawn_worker
    worker.init_process()
  File "/usr/local/lib/python3.6/site-packages/gunicorn/workers/ggevent.py", line 162, in init_process
    super().init_process()
  File "/usr/local/lib/python3.6/site-packages/gunicorn/workers/base.py", line 119, in init_process
    self.load_wsgi()
  File "/usr/local/lib/python3.6/site-packages/gunicorn/workers/base.py", line 144, in load_wsgi
    self.wsgi = self.app.wsgi()
  File "/usr/local/lib/python3.6/site-packages/gunicorn/app/base.py", line 67, in wsgi
    self.callable = self.load()
  File "/usr/local/lib/python3.6/site-packages/gunicorn/app/wsgiapp.py", line 49, in load
    return self.load_wsgiapp()
  File "/usr/local/lib/python3.6/site-packages/gunicorn/app/wsgiapp.py", line 39, in load_wsgiapp
    return util.import_app(self.app_uri)
  File "/usr/local/lib/python3.6/site-packages/gunicorn/util.py", line 358, in import_app
    mod = importlib.import_module(module)
  File "/usr/local/lib/python3.6/importlib/__init__.py", line 126, in import_module
    return _bootstrap._gcd_import(name[level:], package, level)
  File "<frozen importlib._bootstrap>", line 994, in _gcd_import
  File "<frozen importlib._bootstrap>", line 971, in _find_and_load
  File "<frozen importlib._bootstrap>", line 955, in _find_and_load_unlocked
  File "<frozen importlib._bootstrap>", line 665, in _load_unlocked
  File "<frozen importlib._bootstrap_external>", line 678, in exec_module
  File "<frozen importlib._bootstrap>", line 219, in _call_with_frames_removed
  File "/app/app/app.py", line 6, in <module>
    from search import get_similar_tovar
  File "/app/app/search.py", line 14, in <module>
    data = pd.read_excel('../test_data/data.xlsx')
  File "/usr/local/lib/python3.6/site-packages/pandas/io/excel/_base.py", line 304, in read_excel
    io = ExcelFile(io, engine=engine)
  File "/usr/local/lib/python3.6/site-packages/pandas/io/excel/_base.py", line 821, in __init__
    self._reader = self._engines[engine](self._io)
  File "/usr/local/lib/python3.6/site-packages/pandas/io/excel/_xlrd.py", line 20, in __init__
    import_optional_dependency("xlrd", extra=err_msg)
  File "/usr/local/lib/python3.6/site-packages/pandas/compat/_optional.py", line 92, in import_optional_dependency
    raise ImportError(msg) from None
ImportError: Missing optional dependency 'xlrd'. Install xlrd >= 1.0.0 for Excel support Use pip or conda to install xlrd.
[2020-02-01 17:35:21 +0000] [14] [INFO] Worker exiting (pid: 14)
[2020-02-01 17:35:51 +0000] [10] [INFO] Shutting down: Master
[2020-02-01 17:35:51 +0000] [10] [INFO] Reason: Worker failed to boot.
[2020-02-01 17:37:14 +0000] [9] [INFO] Starting gunicorn 20.0.4
[2020-02-01 17:37:14 +0000] [9] [INFO] Listening at: http://0.0.0.0:8888 (9)
[2020-02-01 17:37:14 +0000] [9] [INFO] Using worker: gevent
[2020-02-01 17:37:14 +0000] [12] [INFO] Booting worker with pid: 12
[2020-02-01 17:37:14 +0000] [13] [INFO] Booting worker with pid: 13
[2020-02-01 17:37:14 +0000] [12] [ERROR] Exception in worker process
Traceback (most recent call last):
  File "/usr/local/lib/python3.6/site-packages/gunicorn/arbiter.py", line 583, in spawn_worker
    worker.init_process()
  File "/usr/local/lib/python3.6/site-packages/gunicorn/workers/ggevent.py", line 162, in init_process
    super().init_process()
  File "/usr/local/lib/python3.6/site-packages/gunicorn/workers/base.py", line 119, in init_process
    self.load_wsgi()
  File "/usr/local/lib/python3.6/site-packages/gunicorn/workers/base.py", line 144, in load_wsgi
    self.wsgi = self.app.wsgi()
  File "/usr/local/lib/python3.6/site-packages/gunicorn/app/base.py", line 67, in wsgi
    self.callable = self.load()
  File "/usr/local/lib/python3.6/site-packages/gunicorn/app/wsgiapp.py", line 49, in load
    return self.load_wsgiapp()
  File "/usr/local/lib/python3.6/site-packages/gunicorn/app/wsgiapp.py", line 39, in load_wsgiapp
    return util.import_app(self.app_uri)
  File "/usr/local/lib/python3.6/site-packages/gunicorn/util.py", line 358, in import_app
    mod = importlib.import_module(module)
  File "/usr/local/lib/python3.6/importlib/__init__.py", line 126, in import_module
    return _bootstrap._gcd_import(name[level:], package, level)
  File "<frozen importlib._bootstrap>", line 994, in _gcd_import
  File "<frozen importlib._bootstrap>", line 971, in _find_and_load
  File "<frozen importlib._bootstrap>", line 955, in _find_and_load_unlocked
  File "<frozen importlib._bootstrap>", line 665, in _load_unlocked
  File "<frozen importlib._bootstrap_external>", line 678, in exec_module
  File "<frozen importlib._bootstrap>", line 219, in _call_with_frames_removed
  File "/app/app/app.py", line 6, in <module>
    from search import get_similar_tovar
  File "/app/app/search.py", line 14, in <module>
    data = pd.read_excel('../test_data/data.xlsx')
  File "/usr/local/lib/python3.6/site-packages/pandas/io/excel/_base.py", line 304, in read_excel
    io = ExcelFile(io, engine=engine)
  File "/usr/local/lib/python3.6/site-packages/pandas/io/excel/_base.py", line 821, in __init__
    self._reader = self._engines[engine](self._io)
  File "/usr/local/lib/python3.6/site-packages/pandas/io/excel/_xlrd.py", line 20, in __init__
    import_optional_dependency("xlrd", extra=err_msg)
  File "/usr/local/lib/python3.6/site-packages/pandas/compat/_optional.py", line 92, in import_optional_dependency
    raise ImportError(msg) from None
ImportError: Missing optional dependency 'xlrd'. Install xlrd >= 1.0.0 for Excel support Use pip or conda to install xlrd.
[2020-02-01 17:37:14 +0000] [12] [INFO] Worker exiting (pid: 12)
[2020-02-01 17:37:15 +0000] [13] [ERROR] Exception in worker process
Traceback (most recent call last):
  File "/usr/local/lib/python3.6/site-packages/gunicorn/arbiter.py", line 583, in spawn_worker
    worker.init_process()
  File "/usr/local/lib/python3.6/site-packages/gunicorn/workers/ggevent.py", line 162, in init_process
    super().init_process()
  File "/usr/local/lib/python3.6/site-packages/gunicorn/workers/base.py", line 119, in init_process
    self.load_wsgi()
  File "/usr/local/lib/python3.6/site-packages/gunicorn/workers/base.py", line 144, in load_wsgi
    self.wsgi = self.app.wsgi()
  File "/usr/local/lib/python3.6/site-packages/gunicorn/app/base.py", line 67, in wsgi
    self.callable = self.load()
  File "/usr/local/lib/python3.6/site-packages/gunicorn/app/wsgiapp.py", line 49, in load
    return self.load_wsgiapp()
  File "/usr/local/lib/python3.6/site-packages/gunicorn/app/wsgiapp.py", line 39, in load_wsgiapp
    return util.import_app(self.app_uri)
  File "/usr/local/lib/python3.6/site-packages/gunicorn/util.py", line 358, in import_app
    mod = importlib.import_module(module)
  File "/usr/local/lib/python3.6/importlib/__init__.py", line 126, in import_module
    return _bootstrap._gcd_import(name[level:], package, level)
  File "<frozen importlib._bootstrap>", line 994, in _gcd_import
  File "<frozen importlib._bootstrap>", line 971, in _find_and_load
  File "<frozen importlib._bootstrap>", line 955, in _find_and_load_unlocked
  File "<frozen importlib._bootstrap>", line 665, in _load_unlocked
  File "<frozen importlib._bootstrap_external>", line 678, in exec_module
  File "<frozen importlib._bootstrap>", line 219, in _call_with_frames_removed
  File "/app/app/app.py", line 6, in <module>
    from search import get_similar_tovar
  File "/app/app/search.py", line 14, in <module>
    data = pd.read_excel('../test_data/data.xlsx')
  File "/usr/local/lib/python3.6/site-packages/pandas/io/excel/_base.py", line 304, in read_excel
    io = ExcelFile(io, engine=engine)
  File "/usr/local/lib/python3.6/site-packages/pandas/io/excel/_base.py", line 821, in __init__
    self._reader = self._engines[engine](self._io)
  File "/usr/local/lib/python3.6/site-packages/pandas/io/excel/_xlrd.py", line 20, in __init__
    import_optional_dependency("xlrd", extra=err_msg)
  File "/usr/local/lib/python3.6/site-packages/pandas/compat/_optional.py", line 92, in import_optional_dependency
    raise ImportError(msg) from None
ImportError: Missing optional dependency 'xlrd'. Install xlrd >= 1.0.0 for Excel support Use pip or conda to install xlrd.
[2020-02-01 17:37:15 +0000] [13] [INFO] Worker exiting (pid: 13)
[2020-02-01 17:37:15 +0000] [9] [INFO] Shutting down: Master
[2020-02-01 17:37:15 +0000] [9] [INFO] Reason: Worker failed to boot.
[2020-02-01 17:40:57 +0000] [10] [INFO] Starting gunicorn 20.0.4
[2020-02-01 17:40:57 +0000] [10] [INFO] Listening at: http://0.0.0.0:7777 (10)
[2020-02-01 17:40:57 +0000] [10] [INFO] Using worker: gevent
[2020-02-01 17:40:57 +0000] [13] [INFO] Booting worker with pid: 13
[2020-02-01 17:40:57 +0000] [14] [INFO] Booting worker with pid: 14
[2020-02-01 17:40:58 +0000] [13] [ERROR] Exception in worker process
Traceback (most recent call last):
  File "/usr/local/lib/python3.6/site-packages/gunicorn/arbiter.py", line 583, in spawn_worker
    worker.init_process()
  File "/usr/local/lib/python3.6/site-packages/gunicorn/workers/ggevent.py", line 162, in init_process
    super().init_process()
  File "/usr/local/lib/python3.6/site-packages/gunicorn/workers/base.py", line 119, in init_process
    self.load_wsgi()
  File "/usr/local/lib/python3.6/site-packages/gunicorn/workers/base.py", line 144, in load_wsgi
    self.wsgi = self.app.wsgi()
  File "/usr/local/lib/python3.6/site-packages/gunicorn/app/base.py", line 67, in wsgi
    self.callable = self.load()
  File "/usr/local/lib/python3.6/site-packages/gunicorn/app/wsgiapp.py", line 49, in load
    return self.load_wsgiapp()
  File "/usr/local/lib/python3.6/site-packages/gunicorn/app/wsgiapp.py", line 39, in load_wsgiapp
    return util.import_app(self.app_uri)
  File "/usr/local/lib/python3.6/site-packages/gunicorn/util.py", line 358, in import_app
    mod = importlib.import_module(module)
  File "/usr/local/lib/python3.6/importlib/__init__.py", line 126, in import_module
    return _bootstrap._gcd_import(name[level:], package, level)
  File "<frozen importlib._bootstrap>", line 994, in _gcd_import
  File "<frozen importlib._bootstrap>", line 971, in _find_and_load
  File "<frozen importlib._bootstrap>", line 955, in _find_and_load_unlocked
  File "<frozen importlib._bootstrap>", line 665, in _load_unlocked
  File "<frozen importlib._bootstrap_external>", line 678, in exec_module
  File "<frozen importlib._bootstrap>", line 219, in _call_with_frames_removed
  File "/app/app/app.py", line 6, in <module>
    from search import get_similar_tovar
  File "/app/app/search.py", line 14, in <module>
    data = pd.read_excel('../test_data/data.xlsx')
  File "/usr/local/lib/python3.6/site-packages/pandas/io/excel/_base.py", line 304, in read_excel
    io = ExcelFile(io, engine=engine)
  File "/usr/local/lib/python3.6/site-packages/pandas/io/excel/_base.py", line 821, in __init__
    self._reader = self._engines[engine](self._io)
  File "/usr/local/lib/python3.6/site-packages/pandas/io/excel/_xlrd.py", line 20, in __init__
    import_optional_dependency("xlrd", extra=err_msg)
  File "/usr/local/lib/python3.6/site-packages/pandas/compat/_optional.py", line 92, in import_optional_dependency
    raise ImportError(msg) from None
ImportError: Missing optional dependency 'xlrd'. Install xlrd >= 1.0.0 for Excel support Use pip or conda to install xlrd.
[2020-02-01 17:40:58 +0000] [13] [INFO] Worker exiting (pid: 13)
[2020-02-01 17:40:58 +0000] [14] [ERROR] Exception in worker process
Traceback (most recent call last):
  File "/usr/local/lib/python3.6/site-packages/gunicorn/arbiter.py", line 583, in spawn_worker
    worker.init_process()
  File "/usr/local/lib/python3.6/site-packages/gunicorn/workers/ggevent.py", line 162, in init_process
    super().init_process()
  File "/usr/local/lib/python3.6/site-packages/gunicorn/workers/base.py", line 119, in init_process
    self.load_wsgi()
  File "/usr/local/lib/python3.6/site-packages/gunicorn/workers/base.py", line 144, in load_wsgi
    self.wsgi = self.app.wsgi()
  File "/usr/local/lib/python3.6/site-packages/gunicorn/app/base.py", line 67, in wsgi
    self.callable = self.load()
  File "/usr/local/lib/python3.6/site-packages/gunicorn/app/wsgiapp.py", line 49, in load
    return self.load_wsgiapp()
  File "/usr/local/lib/python3.6/site-packages/gunicorn/app/wsgiapp.py", line 39, in load_wsgiapp
    return util.import_app(self.app_uri)
  File "/usr/local/lib/python3.6/site-packages/gunicorn/util.py", line 358, in import_app
    mod = importlib.import_module(module)
  File "/usr/local/lib/python3.6/importlib/__init__.py", line 126, in import_module
    return _bootstrap._gcd_import(name[level:], package, level)
  File "<frozen importlib._bootstrap>", line 994, in _gcd_import
  File "<frozen importlib._bootstrap>", line 971, in _find_and_load
  File "<frozen importlib._bootstrap>", line 955, in _find_and_load_unlocked
  File "<frozen importlib._bootstrap>", line 665, in _load_unlocked
  File "<frozen importlib._bootstrap_external>", line 678, in exec_module
  File "<frozen importlib._bootstrap>", line 219, in _call_with_frames_removed
  File "/app/app/app.py", line 6, in <module>
    from search import get_similar_tovar
  File "/app/app/search.py", line 14, in <module>
    data = pd.read_excel('../test_data/data.xlsx')
  File "/usr/local/lib/python3.6/site-packages/pandas/io/excel/_base.py", line 304, in read_excel
    io = ExcelFile(io, engine=engine)
  File "/usr/local/lib/python3.6/site-packages/pandas/io/excel/_base.py", line 821, in __init__
    self._reader = self._engines[engine](self._io)
  File "/usr/local/lib/python3.6/site-packages/pandas/io/excel/_xlrd.py", line 20, in __init__
    import_optional_dependency("xlrd", extra=err_msg)
  File "/usr/local/lib/python3.6/site-packages/pandas/compat/_optional.py", line 92, in import_optional_dependency
    raise ImportError(msg) from None
ImportError: Missing optional dependency 'xlrd'. Install xlrd >= 1.0.0 for Excel support Use pip or conda to install xlrd.
[2020-02-01 17:40:58 +0000] [14] [INFO] Worker exiting (pid: 14)
[2020-02-01 17:40:58 +0000] [10] [INFO] Shutting down: Master
[2020-02-01 17:40:58 +0000] [10] [INFO] Reason: Worker failed to boot.
[2020-02-01 17:41:04 +0000] [9] [INFO] Starting gunicorn 20.0.4
[2020-02-01 17:41:04 +0000] [9] [INFO] Listening at: http://0.0.0.0:7777 (9)
[2020-02-01 17:41:04 +0000] [9] [INFO] Using worker: gevent
[2020-02-01 17:41:04 +0000] [12] [INFO] Booting worker with pid: 12
[2020-02-01 17:41:04 +0000] [13] [INFO] Booting worker with pid: 13
[2020-02-01 17:41:05 +0000] [12] [ERROR] Exception in worker process
Traceback (most recent call last):
  File "/usr/local/lib/python3.6/site-packages/gunicorn/arbiter.py", line 583, in spawn_worker
    worker.init_process()
  File "/usr/local/lib/python3.6/site-packages/gunicorn/workers/ggevent.py", line 162, in init_process
    super().init_process()
  File "/usr/local/lib/python3.6/site-packages/gunicorn/workers/base.py", line 119, in init_process
    self.load_wsgi()
  File "/usr/local/lib/python3.6/site-packages/gunicorn/workers/base.py", line 144, in load_wsgi
    self.wsgi = self.app.wsgi()
  File "/usr/local/lib/python3.6/site-packages/gunicorn/app/base.py", line 67, in wsgi
    self.callable = self.load()
  File "/usr/local/lib/python3.6/site-packages/gunicorn/app/wsgiapp.py", line 49, in load
    return self.load_wsgiapp()
  File "/usr/local/lib/python3.6/site-packages/gunicorn/app/wsgiapp.py", line 39, in load_wsgiapp
    return util.import_app(self.app_uri)
  File "/usr/local/lib/python3.6/site-packages/gunicorn/util.py", line 358, in import_app
    mod = importlib.import_module(module)
  File "/usr/local/lib/python3.6/importlib/__init__.py", line 126, in import_module
    return _bootstrap._gcd_import(name[level:], package, level)
  File "<frozen importlib._bootstrap>", line 994, in _gcd_import
  File "<frozen importlib._bootstrap>", line 971, in _find_and_load
  File "<frozen importlib._bootstrap>", line 955, in _find_and_load_unlocked
  File "<frozen importlib._bootstrap>", line 665, in _load_unlocked
  File "<frozen importlib._bootstrap_external>", line 678, in exec_module
  File "<frozen importlib._bootstrap>", line 219, in _call_with_frames_removed
  File "/app/app/app.py", line 6, in <module>
    from search import get_similar_tovar
  File "/app/app/search.py", line 14, in <module>
    data = pd.read_excel('../test_data/data.xlsx')
  File "/usr/local/lib/python3.6/site-packages/pandas/io/excel/_base.py", line 304, in read_excel
    io = ExcelFile(io, engine=engine)
  File "/usr/local/lib/python3.6/site-packages/pandas/io/excel/_base.py", line 821, in __init__
    self._reader = self._engines[engine](self._io)
  File "/usr/local/lib/python3.6/site-packages/pandas/io/excel/_xlrd.py", line 20, in __init__
    import_optional_dependency("xlrd", extra=err_msg)
  File "/usr/local/lib/python3.6/site-packages/pandas/compat/_optional.py", line 92, in import_optional_dependency
    raise ImportError(msg) from None
ImportError: Missing optional dependency 'xlrd'. Install xlrd >= 1.0.0 for Excel support Use pip or conda to install xlrd.
[2020-02-01 17:41:05 +0000] [12] [INFO] Worker exiting (pid: 12)
[2020-02-01 17:41:05 +0000] [13] [ERROR] Exception in worker process
Traceback (most recent call last):
  File "/usr/local/lib/python3.6/site-packages/gunicorn/arbiter.py", line 583, in spawn_worker
    worker.init_process()
  File "/usr/local/lib/python3.6/site-packages/gunicorn/workers/ggevent.py", line 162, in init_process
    super().init_process()
  File "/usr/local/lib/python3.6/site-packages/gunicorn/workers/base.py", line 119, in init_process
    self.load_wsgi()
  File "/usr/local/lib/python3.6/site-packages/gunicorn/workers/base.py", line 144, in load_wsgi
    self.wsgi = self.app.wsgi()
  File "/usr/local/lib/python3.6/site-packages/gunicorn/app/base.py", line 67, in wsgi
    self.callable = self.load()
  File "/usr/local/lib/python3.6/site-packages/gunicorn/app/wsgiapp.py", line 49, in load
    return self.load_wsgiapp()
  File "/usr/local/lib/python3.6/site-packages/gunicorn/app/wsgiapp.py", line 39, in load_wsgiapp
    return util.import_app(self.app_uri)
  File "/usr/local/lib/python3.6/site-packages/gunicorn/util.py", line 358, in import_app
    mod = importlib.import_module(module)
  File "/usr/local/lib/python3.6/importlib/__init__.py", line 126, in import_module
    return _bootstrap._gcd_import(name[level:], package, level)
  File "<frozen importlib._bootstrap>", line 994, in _gcd_import
  File "<frozen importlib._bootstrap>", line 971, in _find_and_load
  File "<frozen importlib._bootstrap>", line 955, in _find_and_load_unlocked
  File "<frozen importlib._bootstrap>", line 665, in _load_unlocked
  File "<frozen importlib._bootstrap_external>", line 678, in exec_module
  File "<frozen importlib._bootstrap>", line 219, in _call_with_frames_removed
  File "/app/app/app.py", line 6, in <module>
    from search import get_similar_tovar
  File "/app/app/search.py", line 14, in <module>
    data = pd.read_excel('../test_data/data.xlsx')
  File "/usr/local/lib/python3.6/site-packages/pandas/io/excel/_base.py", line 304, in read_excel
    io = ExcelFile(io, engine=engine)
  File "/usr/local/lib/python3.6/site-packages/pandas/io/excel/_base.py", line 821, in __init__
    self._reader = self._engines[engine](self._io)
  File "/usr/local/lib/python3.6/site-packages/pandas/io/excel/_xlrd.py", line 20, in __init__
    import_optional_dependency("xlrd", extra=err_msg)
  File "/usr/local/lib/python3.6/site-packages/pandas/compat/_optional.py", line 92, in import_optional_dependency
    raise ImportError(msg) from None
ImportError: Missing optional dependency 'xlrd'. Install xlrd >= 1.0.0 for Excel support Use pip or conda to install xlrd.
[2020-02-01 17:41:05 +0000] [13] [INFO] Worker exiting (pid: 13)
[2020-02-01 17:41:05 +0000] [9] [INFO] Shutting down: Master
[2020-02-01 17:41:05 +0000] [9] [INFO] Reason: Worker failed to boot.
[2020-02-01 17:41:28 +0000] [9] [INFO] Starting gunicorn 20.0.4
[2020-02-01 17:41:28 +0000] [9] [INFO] Listening at: http://0.0.0.0:7777 (9)
[2020-02-01 17:41:28 +0000] [9] [INFO] Using worker: gevent
[2020-02-01 17:41:28 +0000] [12] [INFO] Booting worker with pid: 12
[2020-02-01 17:41:28 +0000] [13] [INFO] Booting worker with pid: 13
[2020-02-01 17:41:29 +0000] [12] [ERROR] Exception in worker process
Traceback (most recent call last):
  File "/usr/local/lib/python3.6/site-packages/gunicorn/arbiter.py", line 583, in spawn_worker
    worker.init_process()
  File "/usr/local/lib/python3.6/site-packages/gunicorn/workers/ggevent.py", line 162, in init_process
    super().init_process()
  File "/usr/local/lib/python3.6/site-packages/gunicorn/workers/base.py", line 119, in init_process
    self.load_wsgi()
  File "/usr/local/lib/python3.6/site-packages/gunicorn/workers/base.py", line 144, in load_wsgi
    self.wsgi = self.app.wsgi()
  File "/usr/local/lib/python3.6/site-packages/gunicorn/app/base.py", line 67, in wsgi
    self.callable = self.load()
  File "/usr/local/lib/python3.6/site-packages/gunicorn/app/wsgiapp.py", line 49, in load
    return self.load_wsgiapp()
  File "/usr/local/lib/python3.6/site-packages/gunicorn/app/wsgiapp.py", line 39, in load_wsgiapp
    return util.import_app(self.app_uri)
  File "/usr/local/lib/python3.6/site-packages/gunicorn/util.py", line 358, in import_app
    mod = importlib.import_module(module)
  File "/usr/local/lib/python3.6/importlib/__init__.py", line 126, in import_module
    return _bootstrap._gcd_import(name[level:], package, level)
  File "<frozen importlib._bootstrap>", line 994, in _gcd_import
  File "<frozen importlib._bootstrap>", line 971, in _find_and_load
  File "<frozen importlib._bootstrap>", line 955, in _find_and_load_unlocked
  File "<frozen importlib._bootstrap>", line 665, in _load_unlocked
  File "<frozen importlib._bootstrap_external>", line 678, in exec_module
  File "<frozen importlib._bootstrap>", line 219, in _call_with_frames_removed
  File "/app/app/app.py", line 6, in <module>
    from search import get_similar_tovar
  File "/app/app/search.py", line 14, in <module>
    data = pd.read_excel('../test_data/data.xlsx')
  File "/usr/local/lib/python3.6/site-packages/pandas/io/excel/_base.py", line 304, in read_excel
    io = ExcelFile(io, engine=engine)
  File "/usr/local/lib/python3.6/site-packages/pandas/io/excel/_base.py", line 821, in __init__
    self._reader = self._engines[engine](self._io)
  File "/usr/local/lib/python3.6/site-packages/pandas/io/excel/_xlrd.py", line 20, in __init__
    import_optional_dependency("xlrd", extra=err_msg)
  File "/usr/local/lib/python3.6/site-packages/pandas/compat/_optional.py", line 92, in import_optional_dependency
    raise ImportError(msg) from None
ImportError: Missing optional dependency 'xlrd'. Install xlrd >= 1.0.0 for Excel support Use pip or conda to install xlrd.
[2020-02-01 17:41:29 +0000] [12] [INFO] Worker exiting (pid: 12)
[2020-02-01 17:41:29 +0000] [13] [ERROR] Exception in worker process
Traceback (most recent call last):
  File "/usr/local/lib/python3.6/site-packages/gunicorn/arbiter.py", line 583, in spawn_worker
    worker.init_process()
  File "/usr/local/lib/python3.6/site-packages/gunicorn/workers/ggevent.py", line 162, in init_process
    super().init_process()
  File "/usr/local/lib/python3.6/site-packages/gunicorn/workers/base.py", line 119, in init_process
    self.load_wsgi()
  File "/usr/local/lib/python3.6/site-packages/gunicorn/workers/base.py", line 144, in load_wsgi
    self.wsgi = self.app.wsgi()
  File "/usr/local/lib/python3.6/site-packages/gunicorn/app/base.py", line 67, in wsgi
    self.callable = self.load()
  File "/usr/local/lib/python3.6/site-packages/gunicorn/app/wsgiapp.py", line 49, in load
    return self.load_wsgiapp()
  File "/usr/local/lib/python3.6/site-packages/gunicorn/app/wsgiapp.py", line 39, in load_wsgiapp
    return util.import_app(self.app_uri)
  File "/usr/local/lib/python3.6/site-packages/gunicorn/util.py", line 358, in import_app
    mod = importlib.import_module(module)
  File "/usr/local/lib/python3.6/importlib/__init__.py", line 126, in import_module
    return _bootstrap._gcd_import(name[level:], package, level)
  File "<frozen importlib._bootstrap>", line 994, in _gcd_import
  File "<frozen importlib._bootstrap>", line 971, in _find_and_load
  File "<frozen importlib._bootstrap>", line 955, in _find_and_load_unlocked
  File "<frozen importlib._bootstrap>", line 665, in _load_unlocked
  File "<frozen importlib._bootstrap_external>", line 678, in exec_module
  File "<frozen importlib._bootstrap>", line 219, in _call_with_frames_removed
  File "/app/app/app.py", line 6, in <module>
    from search import get_similar_tovar
  File "/app/app/search.py", line 14, in <module>
    data = pd.read_excel('../test_data/data.xlsx')
  File "/usr/local/lib/python3.6/site-packages/pandas/io/excel/_base.py", line 304, in read_excel
    io = ExcelFile(io, engine=engine)
  File "/usr/local/lib/python3.6/site-packages/pandas/io/excel/_base.py", line 821, in __init__
    self._reader = self._engines[engine](self._io)
  File "/usr/local/lib/python3.6/site-packages/pandas/io/excel/_xlrd.py", line 20, in __init__
    import_optional_dependency("xlrd", extra=err_msg)
  File "/usr/local/lib/python3.6/site-packages/pandas/compat/_optional.py", line 92, in import_optional_dependency
    raise ImportError(msg) from None
ImportError: Missing optional dependency 'xlrd'. Install xlrd >= 1.0.0 for Excel support Use pip or conda to install xlrd.
[2020-02-01 17:41:29 +0000] [13] [INFO] Worker exiting (pid: 13)
[2020-02-01 17:47:45 +0000] [9] [INFO] Starting gunicorn 20.0.4
[2020-02-01 17:47:45 +0000] [9] [INFO] Listening at: http://0.0.0.0:7777 (9)
[2020-02-01 17:47:45 +0000] [9] [INFO] Using worker: gevent
[2020-02-01 17:47:45 +0000] [12] [INFO] Booting worker with pid: 12
[2020-02-01 17:47:45 +0000] [13] [INFO] Booting worker with pid: 13
[2020-02-01 17:48:15 +0000] [9] [CRITICAL] WORKER TIMEOUT (pid:12)
[2020-02-01 17:48:15 +0000] [9] [CRITICAL] WORKER TIMEOUT (pid:13)
[2020-02-01 17:48:15 +0000] [12] [INFO] Worker exiting (pid: 12)
[2020-02-01 17:48:15 +0000] [13] [INFO] Worker exiting (pid: 13)
[2020-02-01 17:48:16 +0000] [22] [INFO] Booting worker with pid: 22
[2020-02-01 17:48:16 +0000] [23] [INFO] Booting worker with pid: 23
[2020-02-01 17:48:46 +0000] [9] [CRITICAL] WORKER TIMEOUT (pid:22)
[2020-02-01 17:48:46 +0000] [9] [CRITICAL] WORKER TIMEOUT (pid:23)
[2020-02-01 17:48:46 +0000] [23] [INFO] Worker exiting (pid: 23)
[2020-02-01 17:48:46 +0000] [22] [INFO] Worker exiting (pid: 22)
[2020-02-01 17:48:46 +0000] [32] [INFO] Booting worker with pid: 32
[2020-02-01 17:48:46 +0000] [33] [INFO] Booting worker with pid: 33
[2020-02-01 17:49:16 +0000] [9] [CRITICAL] WORKER TIMEOUT (pid:32)
[2020-02-01 17:49:16 +0000] [9] [CRITICAL] WORKER TIMEOUT (pid:33)
[2020-02-01 17:49:16 +0000] [32] [INFO] Worker exiting (pid: 32)
[2020-02-01 17:49:17 +0000] [33] [INFO] Worker exiting (pid: 33)
[2020-02-01 17:49:17 +0000] [42] [INFO] Booting worker with pid: 42
[2020-02-01 17:49:17 +0000] [43] [INFO] Booting worker with pid: 43
[2020-02-01 17:49:47 +0000] [9] [CRITICAL] WORKER TIMEOUT (pid:42)
[2020-02-01 17:49:47 +0000] [9] [CRITICAL] WORKER TIMEOUT (pid:43)
[2020-02-01 17:49:47 +0000] [43] [INFO] Worker exiting (pid: 43)
[2020-02-01 17:49:48 +0000] [42] [INFO] Worker exiting (pid: 42)
[2020-02-01 17:49:48 +0000] [52] [INFO] Booting worker with pid: 52
[2020-02-01 17:49:48 +0000] [53] [INFO] Booting worker with pid: 53
[2020-02-01 17:50:18 +0000] [9] [CRITICAL] WORKER TIMEOUT (pid:52)
[2020-02-01 17:50:18 +0000] [9] [CRITICAL] WORKER TIMEOUT (pid:53)
[2020-02-01 17:50:18 +0000] [53] [INFO] Worker exiting (pid: 53)
[2020-02-01 17:50:18 +0000] [52] [INFO] Worker exiting (pid: 52)
[2020-02-01 17:50:19 +0000] [62] [INFO] Booting worker with pid: 62
[2020-02-01 17:50:19 +0000] [63] [INFO] Booting worker with pid: 63
[2020-02-01 17:50:49 +0000] [9] [CRITICAL] WORKER TIMEOUT (pid:62)
[2020-02-01 17:50:49 +0000] [9] [CRITICAL] WORKER TIMEOUT (pid:63)
[2020-02-01 17:50:49 +0000] [62] [INFO] Worker exiting (pid: 62)
[2020-02-01 17:50:49 +0000] [63] [INFO] Worker exiting (pid: 63)
[2020-02-01 17:50:50 +0000] [72] [INFO] Booting worker with pid: 72
[2020-02-01 17:50:50 +0000] [73] [INFO] Booting worker with pid: 73
[2020-02-01 17:51:20 +0000] [9] [CRITICAL] WORKER TIMEOUT (pid:72)
[2020-02-01 17:51:20 +0000] [9] [CRITICAL] WORKER TIMEOUT (pid:73)
[2020-02-01 17:51:20 +0000] [73] [INFO] Worker exiting (pid: 73)
[2020-02-01 17:51:20 +0000] [72] [INFO] Worker exiting (pid: 72)
[2020-02-01 17:51:21 +0000] [82] [INFO] Booting worker with pid: 82
[2020-02-01 17:51:21 +0000] [83] [INFO] Booting worker with pid: 83
[2020-02-01 17:51:51 +0000] [9] [CRITICAL] WORKER TIMEOUT (pid:82)
[2020-02-01 17:51:51 +0000] [9] [CRITICAL] WORKER TIMEOUT (pid:83)
[2020-02-01 17:51:51 +0000] [83] [INFO] Worker exiting (pid: 83)
[2020-02-01 17:51:51 +0000] [82] [INFO] Worker exiting (pid: 82)
[2020-02-01 17:51:51 +0000] [92] [INFO] Booting worker with pid: 92
[2020-02-01 17:51:51 +0000] [93] [INFO] Booting worker with pid: 93
[2020-02-01 17:52:22 +0000] [9] [CRITICAL] WORKER TIMEOUT (pid:92)
[2020-02-01 17:52:22 +0000] [9] [CRITICAL] WORKER TIMEOUT (pid:93)
[2020-02-01 17:52:22 +0000] [92] [INFO] Worker exiting (pid: 92)
[2020-02-01 17:52:22 +0000] [93] [INFO] Worker exiting (pid: 93)
[2020-02-01 17:52:22 +0000] [102] [INFO] Booting worker with pid: 102
[2020-02-01 17:52:22 +0000] [103] [INFO] Booting worker with pid: 103
[2020-02-01 17:52:52 +0000] [9] [CRITICAL] WORKER TIMEOUT (pid:102)
[2020-02-01 17:52:52 +0000] [9] [CRITICAL] WORKER TIMEOUT (pid:103)
[2020-02-01 17:52:52 +0000] [103] [INFO] Worker exiting (pid: 103)
[2020-02-01 17:52:53 +0000] [102] [INFO] Worker exiting (pid: 102)
[2020-02-01 17:52:53 +0000] [112] [INFO] Booting worker with pid: 112
[2020-02-01 17:52:53 +0000] [113] [INFO] Booting worker with pid: 113
[2020-02-01 17:54:37 +0000] [9] [INFO] Starting gunicorn 20.0.4
[2020-02-01 17:54:37 +0000] [9] [INFO] Listening at: http://0.0.0.0:7777 (9)
[2020-02-01 17:54:37 +0000] [9] [INFO] Using worker: sync
[2020-02-01 17:54:37 +0000] [12] [INFO] Booting worker with pid: 12
[2020-02-01 17:55:07 +0000] [9] [CRITICAL] WORKER TIMEOUT (pid:12)
[2020-02-01 17:55:07 +0000] [12] [INFO] Worker exiting (pid: 12)
[2020-02-01 17:55:08 +0000] [17] [INFO] Booting worker with pid: 17
[2020-02-01 17:55:38 +0000] [9] [CRITICAL] WORKER TIMEOUT (pid:17)
[2020-02-01 17:55:39 +0000] [17] [INFO] Worker exiting (pid: 17)
[2020-02-01 17:55:39 +0000] [22] [INFO] Booting worker with pid: 22
[2020-02-01 17:56:09 +0000] [9] [CRITICAL] WORKER TIMEOUT (pid:22)
[2020-02-01 17:56:09 +0000] [22] [INFO] Worker exiting (pid: 22)
[2020-02-01 17:56:10 +0000] [27] [INFO] Booting worker with pid: 27
[2020-02-01 18:03:40 +0000] [10] [INFO] Starting gunicorn 20.0.4
[2020-02-01 18:03:40 +0000] [10] [INFO] Listening at: http://0.0.0.0:7777 (10)
[2020-02-01 18:03:40 +0000] [10] [INFO] Using worker: sync
[2020-02-01 18:03:40 +0000] [17] [INFO] Booting worker with pid: 17
[2020-02-01 18:08:08 +0000] [9] [INFO] Starting gunicorn 20.0.4
[2020-02-01 18:08:08 +0000] [9] [INFO] Listening at: http://0.0.0.0:7777 (9)
[2020-02-01 18:08:08 +0000] [9] [INFO] Using worker: gevent
[2020-02-01 18:08:08 +0000] [16] [INFO] Booting worker with pid: 16
[2020-02-01 18:08:08 +0000] [17] [INFO] Booting worker with pid: 17
[2020-02-01 18:08:08 +0000] [18] [INFO] Booting worker with pid: 18
[2020-02-01 18:22:23 +0000] [18] [INFO] Worker reloading: /app/app/app.py modified
[2020-02-01 18:22:23 +0000] [18] [INFO] Worker exiting (pid: 18)
[2020-02-01 18:22:24 +0000] [16] [INFO] Worker reloading: /app/app/app.py modified
[2020-02-01 18:22:24 +0000] [16] [INFO] Worker exiting (pid: 16)
[2020-02-01 18:22:24 +0000] [17] [INFO] Worker reloading: /app/app/app.py modified
[2020-02-01 18:22:24 +0000] [17] [INFO] Worker exiting (pid: 17)
[2020-02-01 18:22:25 +0000] [19] [INFO] Booting worker with pid: 19
[2020-02-01 18:22:25 +0000] [20] [INFO] Booting worker with pid: 20
[2020-02-01 18:22:25 +0000] [21] [INFO] Booting worker with pid: 21
[2020-02-01 18:22:39 +0000] [21] [INFO] Worker reloading: /app/app/app.py modified
[2020-02-01 18:22:39 +0000] [21] [INFO] Worker exiting (pid: 21)
[2020-02-01 18:22:39 +0000] [19] [INFO] Worker reloading: /app/app/app.py modified
[2020-02-01 18:22:39 +0000] [19] [INFO] Worker exiting (pid: 19)
[2020-02-01 18:22:40 +0000] [20] [INFO] Worker reloading: /app/app/app.py modified
[2020-02-01 18:22:40 +0000] [20] [INFO] Worker exiting (pid: 20)
[2020-02-01 18:22:40 +0000] [22] [INFO] Booting worker with pid: 22
[2020-02-01 18:22:41 +0000] [24] [INFO] Booting worker with pid: 24
[2020-02-01 18:22:41 +0000] [25] [INFO] Booting worker with pid: 25
[2020-02-01 18:25:24 +0000] [9] [INFO] Starting gunicorn 20.0.4
[2020-02-01 18:25:24 +0000] [9] [INFO] Listening at: http://0.0.0.0:7777 (9)
[2020-02-01 18:25:24 +0000] [9] [INFO] Using worker: gevent
[2020-02-01 18:25:24 +0000] [16] [INFO] Booting worker with pid: 16
[2020-02-01 18:25:24 +0000] [17] [INFO] Booting worker with pid: 17
[2020-02-01 18:25:24 +0000] [18] [INFO] Booting worker with pid: 18
[2020-02-01 18:55:33 +0000] [17] [INFO] Worker reloading: /app/app/search.py modified
[2020-02-01 18:55:33 +0000] [17] [INFO] Worker exiting (pid: 17)
[2020-02-01 18:55:34 +0000] [16] [INFO] Worker reloading: /app/app/search.py modified
[2020-02-01 18:55:34 +0000] [16] [INFO] Worker exiting (pid: 16)
[2020-02-01 18:55:34 +0000] [18] [INFO] Worker reloading: /app/app/search.py modified
[2020-02-01 18:55:34 +0000] [18] [INFO] Worker exiting (pid: 18)
[2020-02-01 18:55:34 +0000] [19] [INFO] Booting worker with pid: 19
[2020-02-01 18:55:35 +0000] [20] [INFO] Booting worker with pid: 20
[2020-02-01 18:55:35 +0000] [21] [INFO] Booting worker with pid: 21
[2020-02-01 18:57:18 +0000] [9] [INFO] Starting gunicorn 20.0.4
[2020-02-01 18:57:18 +0000] [9] [INFO] Listening at: http://0.0.0.0:7777 (9)
[2020-02-01 18:57:18 +0000] [9] [INFO] Using worker: gevent
[2020-02-01 18:57:18 +0000] [16] [INFO] Booting worker with pid: 16
[2020-02-01 18:57:18 +0000] [17] [INFO] Booting worker with pid: 17
[2020-02-01 18:57:18 +0000] [18] [INFO] Booting worker with pid: 18
[2020-02-01 19:19:26 +0000] [16] [ERROR] Error handling request /api/v1/themes/
Traceback (most recent call last):
  File "/usr/local/lib/python3.6/site-packages/gunicorn/workers/base_async.py", line 55, in handle
    self.handle_request(listener_name, req, client, addr)
  File "/usr/local/lib/python3.6/site-packages/gunicorn/workers/ggevent.py", line 143, in handle_request
    super().handle_request(listener_name, req, sock, addr)
  File "/usr/local/lib/python3.6/site-packages/gunicorn/workers/base_async.py", line 106, in handle_request
    respiter = self.wsgi(environ, resp.start_response)
  File "/usr/local/lib/python3.6/site-packages/flask/app.py", line 2309, in __call__
    return self.wsgi_app(environ, start_response)
  File "/usr/local/lib/python3.6/site-packages/flask/app.py", line 2295, in wsgi_app
    response = self.handle_exception(e)
  File "/usr/local/lib/python3.6/site-packages/flask_cors/extension.py", line 161, in wrapped_function
    return cors_after_request(app.make_response(f(*args, **kwargs)))
  File "/usr/local/lib/python3.6/site-packages/flask/app.py", line 1741, in handle_exception
    reraise(exc_type, exc_value, tb)
  File "/usr/local/lib/python3.6/site-packages/flask/_compat.py", line 35, in reraise
    raise value
  File "/usr/local/lib/python3.6/site-packages/flask/app.py", line 2292, in wsgi_app
    response = self.full_dispatch_request()
  File "/usr/local/lib/python3.6/site-packages/flask/app.py", line 1815, in full_dispatch_request
    rv = self.handle_user_exception(e)
  File "/usr/local/lib/python3.6/site-packages/flask_cors/extension.py", line 161, in wrapped_function
    return cors_after_request(app.make_response(f(*args, **kwargs)))
  File "/usr/local/lib/python3.6/site-packages/flask/app.py", line 1718, in handle_user_exception
    reraise(exc_type, exc_value, tb)
  File "/usr/local/lib/python3.6/site-packages/flask/_compat.py", line 35, in reraise
    raise value
  File "/usr/local/lib/python3.6/site-packages/flask/app.py", line 1813, in full_dispatch_request
    rv = self.dispatch_request()
  File "/usr/local/lib/python3.6/site-packages/flask/app.py", line 1799, in dispatch_request
    return self.view_functions[rule.endpoint](**req.view_args)
  File "/usr/local/lib/python3.6/site-packages/flask_cors/decorator.py", line 128, in wrapped_function
    resp = make_response(f(*args, **kwargs))
  File "/app/app/app.py", line 41, in task_processing_themes_processing
    result = get_similar_tovar(req['text'])
KeyError: 'text'
[2020-02-01 19:19:26 +0000] [16] [ERROR] Error handling request /api/v1/themes/
Traceback (most recent call last):
  File "/usr/local/lib/python3.6/site-packages/gunicorn/workers/base_async.py", line 55, in handle
    self.handle_request(listener_name, req, client, addr)
  File "/usr/local/lib/python3.6/site-packages/gunicorn/workers/ggevent.py", line 143, in handle_request
    super().handle_request(listener_name, req, sock, addr)
  File "/usr/local/lib/python3.6/site-packages/gunicorn/workers/base_async.py", line 106, in handle_request
    respiter = self.wsgi(environ, resp.start_response)
  File "/usr/local/lib/python3.6/site-packages/flask/app.py", line 2309, in __call__
    return self.wsgi_app(environ, start_response)
  File "/usr/local/lib/python3.6/site-packages/flask/app.py", line 2295, in wsgi_app
    response = self.handle_exception(e)
  File "/usr/local/lib/python3.6/site-packages/flask_cors/extension.py", line 161, in wrapped_function
    return cors_after_request(app.make_response(f(*args, **kwargs)))
  File "/usr/local/lib/python3.6/site-packages/flask/app.py", line 1741, in handle_exception
    reraise(exc_type, exc_value, tb)
  File "/usr/local/lib/python3.6/site-packages/flask/_compat.py", line 35, in reraise
    raise value
  File "/usr/local/lib/python3.6/site-packages/flask/app.py", line 2292, in wsgi_app
    response = self.full_dispatch_request()
  File "/usr/local/lib/python3.6/site-packages/flask/app.py", line 1815, in full_dispatch_request
    rv = self.handle_user_exception(e)
  File "/usr/local/lib/python3.6/site-packages/flask_cors/extension.py", line 161, in wrapped_function
    return cors_after_request(app.make_response(f(*args, **kwargs)))
  File "/usr/local/lib/python3.6/site-packages/flask/app.py", line 1718, in handle_user_exception
    reraise(exc_type, exc_value, tb)
  File "/usr/local/lib/python3.6/site-packages/flask/_compat.py", line 35, in reraise
    raise value
  File "/usr/local/lib/python3.6/site-packages/flask/app.py", line 1813, in full_dispatch_request
    rv = self.dispatch_request()
  File "/usr/local/lib/python3.6/site-packages/flask/app.py", line 1799, in dispatch_request
    return self.view_functions[rule.endpoint](**req.view_args)
  File "/usr/local/lib/python3.6/site-packages/flask_cors/decorator.py", line 128, in wrapped_function
    resp = make_response(f(*args, **kwargs))
  File "/app/app/app.py", line 41, in task_processing_themes_processing
    result = get_similar_tovar(req['text'])
KeyError: 'text'
[2020-02-01 19:19:26 +0000] [16] [ERROR] Error handling request /api/v1/themes/
Traceback (most recent call last):
  File "/usr/local/lib/python3.6/site-packages/gunicorn/workers/base_async.py", line 55, in handle
    self.handle_request(listener_name, req, client, addr)
  File "/usr/local/lib/python3.6/site-packages/gunicorn/workers/ggevent.py", line 143, in handle_request
    super().handle_request(listener_name, req, sock, addr)
  File "/usr/local/lib/python3.6/site-packages/gunicorn/workers/base_async.py", line 106, in handle_request
    respiter = self.wsgi(environ, resp.start_response)
  File "/usr/local/lib/python3.6/site-packages/flask/app.py", line 2309, in __call__
    return self.wsgi_app(environ, start_response)
  File "/usr/local/lib/python3.6/site-packages/flask/app.py", line 2295, in wsgi_app
    response = self.handle_exception(e)
  File "/usr/local/lib/python3.6/site-packages/flask_cors/extension.py", line 161, in wrapped_function
    return cors_after_request(app.make_response(f(*args, **kwargs)))
  File "/usr/local/lib/python3.6/site-packages/flask/app.py", line 1741, in handle_exception
    reraise(exc_type, exc_value, tb)
  File "/usr/local/lib/python3.6/site-packages/flask/_compat.py", line 35, in reraise
    raise value
  File "/usr/local/lib/python3.6/site-packages/flask/app.py", line 2292, in wsgi_app
    response = self.full_dispatch_request()
  File "/usr/local/lib/python3.6/site-packages/flask/app.py", line 1815, in full_dispatch_request
    rv = self.handle_user_exception(e)
  File "/usr/local/lib/python3.6/site-packages/flask_cors/extension.py", line 161, in wrapped_function
    return cors_after_request(app.make_response(f(*args, **kwargs)))
  File "/usr/local/lib/python3.6/site-packages/flask/app.py", line 1718, in handle_user_exception
    reraise(exc_type, exc_value, tb)
  File "/usr/local/lib/python3.6/site-packages/flask/_compat.py", line 35, in reraise
    raise value
  File "/usr/local/lib/python3.6/site-packages/flask/app.py", line 1813, in full_dispatch_request
    rv = self.dispatch_request()
  File "/usr/local/lib/python3.6/site-packages/flask/app.py", line 1799, in dispatch_request
    return self.view_functions[rule.endpoint](**req.view_args)
  File "/usr/local/lib/python3.6/site-packages/flask_cors/decorator.py", line 128, in wrapped_function
    resp = make_response(f(*args, **kwargs))
  File "/app/app/app.py", line 41, in task_processing_themes_processing
    result = get_similar_tovar(req['text'])
KeyError: 'text'
[2020-02-01 19:19:26 +0000] [18] [ERROR] Error handling request /api/v1/themes/
Traceback (most recent call last):
  File "/usr/local/lib/python3.6/site-packages/gunicorn/workers/base_async.py", line 55, in handle
    self.handle_request(listener_name, req, client, addr)
  File "/usr/local/lib/python3.6/site-packages/gunicorn/workers/ggevent.py", line 143, in handle_request
    super().handle_request(listener_name, req, sock, addr)
  File "/usr/local/lib/python3.6/site-packages/gunicorn/workers/base_async.py", line 106, in handle_request
    respiter = self.wsgi(environ, resp.start_response)
  File "/usr/local/lib/python3.6/site-packages/flask/app.py", line 2309, in __call__
    return self.wsgi_app(environ, start_response)
  File "/usr/local/lib/python3.6/site-packages/flask/app.py", line 2295, in wsgi_app
    response = self.handle_exception(e)
  File "/usr/local/lib/python3.6/site-packages/flask_cors/extension.py", line 161, in wrapped_function
    return cors_after_request(app.make_response(f(*args, **kwargs)))
  File "/usr/local/lib/python3.6/site-packages/flask/app.py", line 1741, in handle_exception
    reraise(exc_type, exc_value, tb)
  File "/usr/local/lib/python3.6/site-packages/flask/_compat.py", line 35, in reraise
    raise value
  File "/usr/local/lib/python3.6/site-packages/flask/app.py", line 2292, in wsgi_app
    response = self.full_dispatch_request()
  File "/usr/local/lib/python3.6/site-packages/flask/app.py", line 1815, in full_dispatch_request
    rv = self.handle_user_exception(e)
  File "/usr/local/lib/python3.6/site-packages/flask_cors/extension.py", line 161, in wrapped_function
    return cors_after_request(app.make_response(f(*args, **kwargs)))
  File "/usr/local/lib/python3.6/site-packages/flask/app.py", line 1718, in handle_user_exception
    reraise(exc_type, exc_value, tb)
  File "/usr/local/lib/python3.6/site-packages/flask/_compat.py", line 35, in reraise
    raise value
  File "/usr/local/lib/python3.6/site-packages/flask/app.py", line 1813, in full_dispatch_request
    rv = self.dispatch_request()
  File "/usr/local/lib/python3.6/site-packages/flask/app.py", line 1799, in dispatch_request
    return self.view_functions[rule.endpoint](**req.view_args)
  File "/usr/local/lib/python3.6/site-packages/flask_cors/decorator.py", line 128, in wrapped_function
    resp = make_response(f(*args, **kwargs))
  File "/app/app/app.py", line 41, in task_processing_themes_processing
    result = get_similar_tovar(req['text'])
KeyError: 'text'
[2020-02-01 19:19:26 +0000] [17] [ERROR] Error handling request /api/v1/themes/
Traceback (most recent call last):
  File "/usr/local/lib/python3.6/site-packages/gunicorn/workers/base_async.py", line 55, in handle
    self.handle_request(listener_name, req, client, addr)
  File "/usr/local/lib/python3.6/site-packages/gunicorn/workers/ggevent.py", line 143, in handle_request
    super().handle_request(listener_name, req, sock, addr)
  File "/usr/local/lib/python3.6/site-packages/gunicorn/workers/base_async.py", line 106, in handle_request
    respiter = self.wsgi(environ, resp.start_response)
  File "/usr/local/lib/python3.6/site-packages/flask/app.py", line 2309, in __call__
    return self.wsgi_app(environ, start_response)
  File "/usr/local/lib/python3.6/site-packages/flask/app.py", line 2295, in wsgi_app
    response = self.handle_exception(e)
  File "/usr/local/lib/python3.6/site-packages/flask_cors/extension.py", line 161, in wrapped_function
    return cors_after_request(app.make_response(f(*args, **kwargs)))
  File "/usr/local/lib/python3.6/site-packages/flask/app.py", line 1741, in handle_exception
    reraise(exc_type, exc_value, tb)
  File "/usr/local/lib/python3.6/site-packages/flask/_compat.py", line 35, in reraise
    raise value
  File "/usr/local/lib/python3.6/site-packages/flask/app.py", line 2292, in wsgi_app
    response = self.full_dispatch_request()
  File "/usr/local/lib/python3.6/site-packages/flask/app.py", line 1815, in full_dispatch_request
    rv = self.handle_user_exception(e)
  File "/usr/local/lib/python3.6/site-packages/flask_cors/extension.py", line 161, in wrapped_function
    return cors_after_request(app.make_response(f(*args, **kwargs)))
  File "/usr/local/lib/python3.6/site-packages/flask/app.py", line 1718, in handle_user_exception
    reraise(exc_type, exc_value, tb)
  File "/usr/local/lib/python3.6/site-packages/flask/_compat.py", line 35, in reraise
    raise value
  File "/usr/local/lib/python3.6/site-packages/flask/app.py", line 1813, in full_dispatch_request
    rv = self.dispatch_request()
  File "/usr/local/lib/python3.6/site-packages/flask/app.py", line 1799, in dispatch_request
    return self.view_functions[rule.endpoint](**req.view_args)
  File "/usr/local/lib/python3.6/site-packages/flask_cors/decorator.py", line 128, in wrapped_function
    resp = make_response(f(*args, **kwargs))
  File "/app/app/app.py", line 41, in task_processing_themes_processing
    result = get_similar_tovar(req['text'])
KeyError: 'text'
[2020-02-01 19:19:26 +0000] [17] [ERROR] Error handling request /api/v1/themes/
Traceback (most recent call last):
  File "/usr/local/lib/python3.6/site-packages/gunicorn/workers/base_async.py", line 55, in handle
    self.handle_request(listener_name, req, client, addr)
  File "/usr/local/lib/python3.6/site-packages/gunicorn/workers/ggevent.py", line 143, in handle_request
    super().handle_request(listener_name, req, sock, addr)
  File "/usr/local/lib/python3.6/site-packages/gunicorn/workers/base_async.py", line 106, in handle_request
    respiter = self.wsgi(environ, resp.start_response)
  File "/usr/local/lib/python3.6/site-packages/flask/app.py", line 2309, in __call__
    return self.wsgi_app(environ, start_response)
  File "/usr/local/lib/python3.6/site-packages/flask/app.py", line 2295, in wsgi_app
    response = self.handle_exception(e)
  File "/usr/local/lib/python3.6/site-packages/flask_cors/extension.py", line 161, in wrapped_function
    return cors_after_request(app.make_response(f(*args, **kwargs)))
  File "/usr/local/lib/python3.6/site-packages/flask/app.py", line 1741, in handle_exception
    reraise(exc_type, exc_value, tb)
  File "/usr/local/lib/python3.6/site-packages/flask/_compat.py", line 35, in reraise
    raise value
  File "/usr/local/lib/python3.6/site-packages/flask/app.py", line 2292, in wsgi_app
    response = self.full_dispatch_request()
  File "/usr/local/lib/python3.6/site-packages/flask/app.py", line 1815, in full_dispatch_request
    rv = self.handle_user_exception(e)
  File "/usr/local/lib/python3.6/site-packages/flask_cors/extension.py", line 161, in wrapped_function
    return cors_after_request(app.make_response(f(*args, **kwargs)))
  File "/usr/local/lib/python3.6/site-packages/flask/app.py", line 1718, in handle_user_exception
    reraise(exc_type, exc_value, tb)
  File "/usr/local/lib/python3.6/site-packages/flask/_compat.py", line 35, in reraise
    raise value
  File "/usr/local/lib/python3.6/site-packages/flask/app.py", line 1813, in full_dispatch_request
    rv = self.dispatch_request()
  File "/usr/local/lib/python3.6/site-packages/flask/app.py", line 1799, in dispatch_request
    return self.view_functions[rule.endpoint](**req.view_args)
  File "/usr/local/lib/python3.6/site-packages/flask_cors/decorator.py", line 128, in wrapped_function
    resp = make_response(f(*args, **kwargs))
  File "/app/app/app.py", line 41, in task_processing_themes_processing
    result = get_similar_tovar(req['text'])
KeyError: 'text'
[2020-02-01 19:19:26 +0000] [18] [ERROR] Error handling request /api/v1/themes/
Traceback (most recent call last):
  File "/usr/local/lib/python3.6/site-packages/gunicorn/workers/base_async.py", line 55, in handle
    self.handle_request(listener_name, req, client, addr)
  File "/usr/local/lib/python3.6/site-packages/gunicorn/workers/ggevent.py", line 143, in handle_request
    super().handle_request(listener_name, req, sock, addr)
  File "/usr/local/lib/python3.6/site-packages/gunicorn/workers/base_async.py", line 106, in handle_request
    respiter = self.wsgi(environ, resp.start_response)
  File "/usr/local/lib/python3.6/site-packages/flask/app.py", line 2309, in __call__
    return self.wsgi_app(environ, start_response)
  File "/usr/local/lib/python3.6/site-packages/flask/app.py", line 2295, in wsgi_app
    response = self.handle_exception(e)
  File "/usr/local/lib/python3.6/site-packages/flask_cors/extension.py", line 161, in wrapped_function
    return cors_after_request(app.make_response(f(*args, **kwargs)))
  File "/usr/local/lib/python3.6/site-packages/flask/app.py", line 1741, in handle_exception
    reraise(exc_type, exc_value, tb)
  File "/usr/local/lib/python3.6/site-packages/flask/_compat.py", line 35, in reraise
    raise value
  File "/usr/local/lib/python3.6/site-packages/flask/app.py", line 2292, in wsgi_app
    response = self.full_dispatch_request()
  File "/usr/local/lib/python3.6/site-packages/flask/app.py", line 1815, in full_dispatch_request
    rv = self.handle_user_exception(e)
  File "/usr/local/lib/python3.6/site-packages/flask_cors/extension.py", line 161, in wrapped_function
    return cors_after_request(app.make_response(f(*args, **kwargs)))
  File "/usr/local/lib/python3.6/site-packages/flask/app.py", line 1718, in handle_user_exception
    reraise(exc_type, exc_value, tb)
  File "/usr/local/lib/python3.6/site-packages/flask/_compat.py", line 35, in reraise
    raise value
  File "/usr/local/lib/python3.6/site-packages/flask/app.py", line 1813, in full_dispatch_request
    rv = self.dispatch_request()
  File "/usr/local/lib/python3.6/site-packages/flask/app.py", line 1799, in dispatch_request
    return self.view_functions[rule.endpoint](**req.view_args)
  File "/usr/local/lib/python3.6/site-packages/flask_cors/decorator.py", line 128, in wrapped_function
    resp = make_response(f(*args, **kwargs))
  File "/app/app/app.py", line 41, in task_processing_themes_processing
    result = get_similar_tovar(req['text'])
KeyError: 'text'
[2020-02-01 19:19:26 +0000] [18] [ERROR] Error handling request /api/v1/themes/
Traceback (most recent call last):
  File "/usr/local/lib/python3.6/site-packages/gunicorn/workers/base_async.py", line 55, in handle
    self.handle_request(listener_name, req, client, addr)
  File "/usr/local/lib/python3.6/site-packages/gunicorn/workers/ggevent.py", line 143, in handle_request
    super().handle_request(listener_name, req, sock, addr)
  File "/usr/local/lib/python3.6/site-packages/gunicorn/workers/base_async.py", line 106, in handle_request
    respiter = self.wsgi(environ, resp.start_response)
  File "/usr/local/lib/python3.6/site-packages/flask/app.py", line 2309, in __call__
    return self.wsgi_app(environ, start_response)
  File "/usr/local/lib/python3.6/site-packages/flask/app.py", line 2295, in wsgi_app
    response = self.handle_exception(e)
  File "/usr/local/lib/python3.6/site-packages/flask_cors/extension.py", line 161, in wrapped_function
    return cors_after_request(app.make_response(f(*args, **kwargs)))
  File "/usr/local/lib/python3.6/site-packages/flask/app.py", line 1741, in handle_exception
    reraise(exc_type, exc_value, tb)
  File "/usr/local/lib/python3.6/site-packages/flask/_compat.py", line 35, in reraise
    raise value
  File "/usr/local/lib/python3.6/site-packages/flask/app.py", line 2292, in wsgi_app
    response = self.full_dispatch_request()
  File "/usr/local/lib/python3.6/site-packages/flask/app.py", line 1815, in full_dispatch_request
    rv = self.handle_user_exception(e)
  File "/usr/local/lib/python3.6/site-packages/flask_cors/extension.py", line 161, in wrapped_function
    return cors_after_request(app.make_response(f(*args, **kwargs)))
  File "/usr/local/lib/python3.6/site-packages/flask/app.py", line 1718, in handle_user_exception
    reraise(exc_type, exc_value, tb)
  File "/usr/local/lib/python3.6/site-packages/flask/_compat.py", line 35, in reraise
    raise value
  File "/usr/local/lib/python3.6/site-packages/flask/app.py", line 1813, in full_dispatch_request
    rv = self.dispatch_request()
  File "/usr/local/lib/python3.6/site-packages/flask/app.py", line 1799, in dispatch_request
    return self.view_functions[rule.endpoint](**req.view_args)
  File "/usr/local/lib/python3.6/site-packages/flask_cors/decorator.py", line 128, in wrapped_function
    resp = make_response(f(*args, **kwargs))
  File "/app/app/app.py", line 41, in task_processing_themes_processing
    result = get_similar_tovar(req['text'])
KeyError: 'text'
[2020-02-01 19:19:26 +0000] [17] [ERROR] Error handling request /api/v1/themes/
Traceback (most recent call last):
  File "/usr/local/lib/python3.6/site-packages/gunicorn/workers/base_async.py", line 55, in handle
    self.handle_request(listener_name, req, client, addr)
  File "/usr/local/lib/python3.6/site-packages/gunicorn/workers/ggevent.py", line 143, in handle_request
    super().handle_request(listener_name, req, sock, addr)
  File "/usr/local/lib/python3.6/site-packages/gunicorn/workers/base_async.py", line 106, in handle_request
    respiter = self.wsgi(environ, resp.start_response)
  File "/usr/local/lib/python3.6/site-packages/flask/app.py", line 2309, in __call__
    return self.wsgi_app(environ, start_response)
  File "/usr/local/lib/python3.6/site-packages/flask/app.py", line 2295, in wsgi_app
    response = self.handle_exception(e)
  File "/usr/local/lib/python3.6/site-packages/flask_cors/extension.py", line 161, in wrapped_function
    return cors_after_request(app.make_response(f(*args, **kwargs)))
  File "/usr/local/lib/python3.6/site-packages/flask/app.py", line 1741, in handle_exception
    reraise(exc_type, exc_value, tb)
  File "/usr/local/lib/python3.6/site-packages/flask/_compat.py", line 35, in reraise
    raise value
  File "/usr/local/lib/python3.6/site-packages/flask/app.py", line 2292, in wsgi_app
    response = self.full_dispatch_request()
  File "/usr/local/lib/python3.6/site-packages/flask/app.py", line 1815, in full_dispatch_request
    rv = self.handle_user_exception(e)
  File "/usr/local/lib/python3.6/site-packages/flask_cors/extension.py", line 161, in wrapped_function
    return cors_after_request(app.make_response(f(*args, **kwargs)))
  File "/usr/local/lib/python3.6/site-packages/flask/app.py", line 1718, in handle_user_exception
    reraise(exc_type, exc_value, tb)
  File "/usr/local/lib/python3.6/site-packages/flask/_compat.py", line 35, in reraise
    raise value
  File "/usr/local/lib/python3.6/site-packages/flask/app.py", line 1813, in full_dispatch_request
    rv = self.dispatch_request()
  File "/usr/local/lib/python3.6/site-packages/flask/app.py", line 1799, in dispatch_request
    return self.view_functions[rule.endpoint](**req.view_args)
  File "/usr/local/lib/python3.6/site-packages/flask_cors/decorator.py", line 128, in wrapped_function
    resp = make_response(f(*args, **kwargs))
  File "/app/app/app.py", line 41, in task_processing_themes_processing
    result = get_similar_tovar(req['text'])
KeyError: 'text'
[2020-02-01 19:19:26 +0000] [17] [ERROR] Error handling request /api/v1/themes/
Traceback (most recent call last):
  File "/usr/local/lib/python3.6/site-packages/gunicorn/workers/base_async.py", line 55, in handle
    self.handle_request(listener_name, req, client, addr)
  File "/usr/local/lib/python3.6/site-packages/gunicorn/workers/ggevent.py", line 143, in handle_request
    super().handle_request(listener_name, req, sock, addr)
  File "/usr/local/lib/python3.6/site-packages/gunicorn/workers/base_async.py", line 106, in handle_request
    respiter = self.wsgi(environ, resp.start_response)
  File "/usr/local/lib/python3.6/site-packages/flask/app.py", line 2309, in __call__
    return self.wsgi_app(environ, start_response)
  File "/usr/local/lib/python3.6/site-packages/flask/app.py", line 2295, in wsgi_app
    response = self.handle_exception(e)
  File "/usr/local/lib/python3.6/site-packages/flask_cors/extension.py", line 161, in wrapped_function
    return cors_after_request(app.make_response(f(*args, **kwargs)))
  File "/usr/local/lib/python3.6/site-packages/flask/app.py", line 1741, in handle_exception
    reraise(exc_type, exc_value, tb)
  File "/usr/local/lib/python3.6/site-packages/flask/_compat.py", line 35, in reraise
    raise value
  File "/usr/local/lib/python3.6/site-packages/flask/app.py", line 2292, in wsgi_app
    response = self.full_dispatch_request()
  File "/usr/local/lib/python3.6/site-packages/flask/app.py", line 1815, in full_dispatch_request
    rv = self.handle_user_exception(e)
  File "/usr/local/lib/python3.6/site-packages/flask_cors/extension.py", line 161, in wrapped_function
    return cors_after_request(app.make_response(f(*args, **kwargs)))
  File "/usr/local/lib/python3.6/site-packages/flask/app.py", line 1718, in handle_user_exception
    reraise(exc_type, exc_value, tb)
  File "/usr/local/lib/python3.6/site-packages/flask/_compat.py", line 35, in reraise
    raise value
  File "/usr/local/lib/python3.6/site-packages/flask/app.py", line 1813, in full_dispatch_request
    rv = self.dispatch_request()
  File "/usr/local/lib/python3.6/site-packages/flask/app.py", line 1799, in dispatch_request
    return self.view_functions[rule.endpoint](**req.view_args)
  File "/usr/local/lib/python3.6/site-packages/flask_cors/decorator.py", line 128, in wrapped_function
    resp = make_response(f(*args, **kwargs))
  File "/app/app/app.py", line 41, in task_processing_themes_processing
    result = get_similar_tovar(req['text'])
KeyError: 'text'
[2020-02-01 19:19:26 +0000] [17] [ERROR] Error handling request /api/v1/themes/
Traceback (most recent call last):
  File "/usr/local/lib/python3.6/site-packages/gunicorn/workers/base_async.py", line 55, in handle
    self.handle_request(listener_name, req, client, addr)
  File "/usr/local/lib/python3.6/site-packages/gunicorn/workers/ggevent.py", line 143, in handle_request
    super().handle_request(listener_name, req, sock, addr)
  File "/usr/local/lib/python3.6/site-packages/gunicorn/workers/base_async.py", line 106, in handle_request
    respiter = self.wsgi(environ, resp.start_response)
  File "/usr/local/lib/python3.6/site-packages/flask/app.py", line 2309, in __call__
    return self.wsgi_app(environ, start_response)
  File "/usr/local/lib/python3.6/site-packages/flask/app.py", line 2295, in wsgi_app
    response = self.handle_exception(e)
  File "/usr/local/lib/python3.6/site-packages/flask_cors/extension.py", line 161, in wrapped_function
    return cors_after_request(app.make_response(f(*args, **kwargs)))
  File "/usr/local/lib/python3.6/site-packages/flask/app.py", line 1741, in handle_exception
    reraise(exc_type, exc_value, tb)
  File "/usr/local/lib/python3.6/site-packages/flask/_compat.py", line 35, in reraise
    raise value
  File "/usr/local/lib/python3.6/site-packages/flask/app.py", line 2292, in wsgi_app
    response = self.full_dispatch_request()
  File "/usr/local/lib/python3.6/site-packages/flask/app.py", line 1815, in full_dispatch_request
    rv = self.handle_user_exception(e)
  File "/usr/local/lib/python3.6/site-packages/flask_cors/extension.py", line 161, in wrapped_function
    return cors_after_request(app.make_response(f(*args, **kwargs)))
  File "/usr/local/lib/python3.6/site-packages/flask/app.py", line 1718, in handle_user_exception
    reraise(exc_type, exc_value, tb)
  File "/usr/local/lib/python3.6/site-packages/flask/_compat.py", line 35, in reraise
    raise value
  File "/usr/local/lib/python3.6/site-packages/flask/app.py", line 1813, in full_dispatch_request
    rv = self.dispatch_request()
  File "/usr/local/lib/python3.6/site-packages/flask/app.py", line 1799, in dispatch_request
    return self.view_functions[rule.endpoint](**req.view_args)
  File "/usr/local/lib/python3.6/site-packages/flask_cors/decorator.py", line 128, in wrapped_function
    resp = make_response(f(*args, **kwargs))
  File "/app/app/app.py", line 41, in task_processing_themes_processing
    result = get_similar_tovar(req['text'])
KeyError: 'text'
[2020-02-01 19:19:26 +0000] [18] [ERROR] Error handling request /api/v1/themes/
Traceback (most recent call last):
  File "/usr/local/lib/python3.6/site-packages/gunicorn/workers/base_async.py", line 55, in handle
    self.handle_request(listener_name, req, client, addr)
  File "/usr/local/lib/python3.6/site-packages/gunicorn/workers/ggevent.py", line 143, in handle_request
    super().handle_request(listener_name, req, sock, addr)
  File "/usr/local/lib/python3.6/site-packages/gunicorn/workers/base_async.py", line 106, in handle_request
    respiter = self.wsgi(environ, resp.start_response)
  File "/usr/local/lib/python3.6/site-packages/flask/app.py", line 2309, in __call__
    return self.wsgi_app(environ, start_response)
  File "/usr/local/lib/python3.6/site-packages/flask/app.py", line 2295, in wsgi_app
    response = self.handle_exception(e)
  File "/usr/local/lib/python3.6/site-packages/flask_cors/extension.py", line 161, in wrapped_function
    return cors_after_request(app.make_response(f(*args, **kwargs)))
  File "/usr/local/lib/python3.6/site-packages/flask/app.py", line 1741, in handle_exception
    reraise(exc_type, exc_value, tb)
  File "/usr/local/lib/python3.6/site-packages/flask/_compat.py", line 35, in reraise
    raise value
  File "/usr/local/lib/python3.6/site-packages/flask/app.py", line 2292, in wsgi_app
    response = self.full_dispatch_request()
  File "/usr/local/lib/python3.6/site-packages/flask/app.py", line 1815, in full_dispatch_request
    rv = self.handle_user_exception(e)
  File "/usr/local/lib/python3.6/site-packages/flask_cors/extension.py", line 161, in wrapped_function
    return cors_after_request(app.make_response(f(*args, **kwargs)))
  File "/usr/local/lib/python3.6/site-packages/flask/app.py", line 1718, in handle_user_exception
    reraise(exc_type, exc_value, tb)
  File "/usr/local/lib/python3.6/site-packages/flask/_compat.py", line 35, in reraise
    raise value
  File "/usr/local/lib/python3.6/site-packages/flask/app.py", line 1813, in full_dispatch_request
    rv = self.dispatch_request()
  File "/usr/local/lib/python3.6/site-packages/flask/app.py", line 1799, in dispatch_request
    return self.view_functions[rule.endpoint](**req.view_args)
  File "/usr/local/lib/python3.6/site-packages/flask_cors/decorator.py", line 128, in wrapped_function
    resp = make_response(f(*args, **kwargs))
  File "/app/app/app.py", line 41, in task_processing_themes_processing
    result = get_similar_tovar(req['text'])
KeyError: 'text'
[2020-02-01 19:19:26 +0000] [18] [ERROR] Error handling request /api/v1/themes/
Traceback (most recent call last):
  File "/usr/local/lib/python3.6/site-packages/gunicorn/workers/base_async.py", line 55, in handle
    self.handle_request(listener_name, req, client, addr)
  File "/usr/local/lib/python3.6/site-packages/gunicorn/workers/ggevent.py", line 143, in handle_request
    super().handle_request(listener_name, req, sock, addr)
  File "/usr/local/lib/python3.6/site-packages/gunicorn/workers/base_async.py", line 106, in handle_request
    respiter = self.wsgi(environ, resp.start_response)
  File "/usr/local/lib/python3.6/site-packages/flask/app.py", line 2309, in __call__
    return self.wsgi_app(environ, start_response)
  File "/usr/local/lib/python3.6/site-packages/flask/app.py", line 2295, in wsgi_app
    response = self.handle_exception(e)
  File "/usr/local/lib/python3.6/site-packages/flask_cors/extension.py", line 161, in wrapped_function
    return cors_after_request(app.make_response(f(*args, **kwargs)))
  File "/usr/local/lib/python3.6/site-packages/flask/app.py", line 1741, in handle_exception
    reraise(exc_type, exc_value, tb)
  File "/usr/local/lib/python3.6/site-packages/flask/_compat.py", line 35, in reraise
    raise value
  File "/usr/local/lib/python3.6/site-packages/flask/app.py", line 2292, in wsgi_app
    response = self.full_dispatch_request()
  File "/usr/local/lib/python3.6/site-packages/flask/app.py", line 1815, in full_dispatch_request
    rv = self.handle_user_exception(e)
  File "/usr/local/lib/python3.6/site-packages/flask_cors/extension.py", line 161, in wrapped_function
    return cors_after_request(app.make_response(f(*args, **kwargs)))
  File "/usr/local/lib/python3.6/site-packages/flask/app.py", line 1718, in handle_user_exception
    reraise(exc_type, exc_value, tb)
  File "/usr/local/lib/python3.6/site-packages/flask/_compat.py", line 35, in reraise
    raise value
  File "/usr/local/lib/python3.6/site-packages/flask/app.py", line 1813, in full_dispatch_request
    rv = self.dispatch_request()
  File "/usr/local/lib/python3.6/site-packages/flask/app.py", line 1799, in dispatch_request
    return self.view_functions[rule.endpoint](**req.view_args)
  File "/usr/local/lib/python3.6/site-packages/flask_cors/decorator.py", line 128, in wrapped_function
    resp = make_response(f(*args, **kwargs))
  File "/app/app/app.py", line 41, in task_processing_themes_processing
    result = get_similar_tovar(req['text'])
KeyError: 'text'
[2020-02-01 19:19:26 +0000] [18] [ERROR] Error handling request /api/v1/themes/
Traceback (most recent call last):
  File "/usr/local/lib/python3.6/site-packages/gunicorn/workers/base_async.py", line 55, in handle
    self.handle_request(listener_name, req, client, addr)
  File "/usr/local/lib/python3.6/site-packages/gunicorn/workers/ggevent.py", line 143, in handle_request
    super().handle_request(listener_name, req, sock, addr)
  File "/usr/local/lib/python3.6/site-packages/gunicorn/workers/base_async.py", line 106, in handle_request
    respiter = self.wsgi(environ, resp.start_response)
  File "/usr/local/lib/python3.6/site-packages/flask/app.py", line 2309, in __call__
    return self.wsgi_app(environ, start_response)
  File "/usr/local/lib/python3.6/site-packages/flask/app.py", line 2295, in wsgi_app
    response = self.handle_exception(e)
  File "/usr/local/lib/python3.6/site-packages/flask_cors/extension.py", line 161, in wrapped_function
    return cors_after_request(app.make_response(f(*args, **kwargs)))
  File "/usr/local/lib/python3.6/site-packages/flask/app.py", line 1741, in handle_exception
    reraise(exc_type, exc_value, tb)
  File "/usr/local/lib/python3.6/site-packages/flask/_compat.py", line 35, in reraise
    raise value
  File "/usr/local/lib/python3.6/site-packages/flask/app.py", line 2292, in wsgi_app
    response = self.full_dispatch_request()
  File "/usr/local/lib/python3.6/site-packages/flask/app.py", line 1815, in full_dispatch_request
    rv = self.handle_user_exception(e)
  File "/usr/local/lib/python3.6/site-packages/flask_cors/extension.py", line 161, in wrapped_function
    return cors_after_request(app.make_response(f(*args, **kwargs)))
  File "/usr/local/lib/python3.6/site-packages/flask/app.py", line 1718, in handle_user_exception
    reraise(exc_type, exc_value, tb)
  File "/usr/local/lib/python3.6/site-packages/flask/_compat.py", line 35, in reraise
    raise value
  File "/usr/local/lib/python3.6/site-packages/flask/app.py", line 1813, in full_dispatch_request
    rv = self.dispatch_request()
  File "/usr/local/lib/python3.6/site-packages/flask/app.py", line 1799, in dispatch_request
    return self.view_functions[rule.endpoint](**req.view_args)
  File "/usr/local/lib/python3.6/site-packages/flask_cors/decorator.py", line 128, in wrapped_function
    resp = make_response(f(*args, **kwargs))
  File "/app/app/app.py", line 41, in task_processing_themes_processing
    result = get_similar_tovar(req['text'])
KeyError: 'text'
[2020-02-01 19:19:26 +0000] [18] [ERROR] Error handling request /api/v1/themes/
Traceback (most recent call last):
  File "/usr/local/lib/python3.6/site-packages/gunicorn/workers/base_async.py", line 55, in handle
    self.handle_request(listener_name, req, client, addr)
  File "/usr/local/lib/python3.6/site-packages/gunicorn/workers/ggevent.py", line 143, in handle_request
    super().handle_request(listener_name, req, sock, addr)
  File "/usr/local/lib/python3.6/site-packages/gunicorn/workers/base_async.py", line 106, in handle_request
    respiter = self.wsgi(environ, resp.start_response)
  File "/usr/local/lib/python3.6/site-packages/flask/app.py", line 2309, in __call__
    return self.wsgi_app(environ, start_response)
  File "/usr/local/lib/python3.6/site-packages/flask/app.py", line 2295, in wsgi_app
    response = self.handle_exception(e)
  File "/usr/local/lib/python3.6/site-packages/flask_cors/extension.py", line 161, in wrapped_function
    return cors_after_request(app.make_response(f(*args, **kwargs)))
  File "/usr/local/lib/python3.6/site-packages/flask/app.py", line 1741, in handle_exception
    reraise(exc_type, exc_value, tb)
  File "/usr/local/lib/python3.6/site-packages/flask/_compat.py", line 35, in reraise
    raise value
  File "/usr/local/lib/python3.6/site-packages/flask/app.py", line 2292, in wsgi_app
    response = self.full_dispatch_request()
  File "/usr/local/lib/python3.6/site-packages/flask/app.py", line 1815, in full_dispatch_request
    rv = self.handle_user_exception(e)
  File "/usr/local/lib/python3.6/site-packages/flask_cors/extension.py", line 161, in wrapped_function
    return cors_after_request(app.make_response(f(*args, **kwargs)))
  File "/usr/local/lib/python3.6/site-packages/flask/app.py", line 1718, in handle_user_exception
    reraise(exc_type, exc_value, tb)
  File "/usr/local/lib/python3.6/site-packages/flask/_compat.py", line 35, in reraise
    raise value
  File "/usr/local/lib/python3.6/site-packages/flask/app.py", line 1813, in full_dispatch_request
    rv = self.dispatch_request()
  File "/usr/local/lib/python3.6/site-packages/flask/app.py", line 1799, in dispatch_request
    return self.view_functions[rule.endpoint](**req.view_args)
  File "/usr/local/lib/python3.6/site-packages/flask_cors/decorator.py", line 128, in wrapped_function
    resp = make_response(f(*args, **kwargs))
  File "/app/app/app.py", line 41, in task_processing_themes_processing
    result = get_similar_tovar(req['text'])
KeyError: 'text'
[2020-02-01 19:19:26 +0000] [16] [ERROR] Error handling request /api/v1/themes/
Traceback (most recent call last):
  File "/usr/local/lib/python3.6/site-packages/gunicorn/workers/base_async.py", line 55, in handle
    self.handle_request(listener_name, req, client, addr)
  File "/usr/local/lib/python3.6/site-packages/gunicorn/workers/ggevent.py", line 143, in handle_request
    super().handle_request(listener_name, req, sock, addr)
  File "/usr/local/lib/python3.6/site-packages/gunicorn/workers/base_async.py", line 106, in handle_request
    respiter = self.wsgi(environ, resp.start_response)
  File "/usr/local/lib/python3.6/site-packages/flask/app.py", line 2309, in __call__
    return self.wsgi_app(environ, start_response)
  File "/usr/local/lib/python3.6/site-packages/flask/app.py", line 2295, in wsgi_app
    response = self.handle_exception(e)
  File "/usr/local/lib/python3.6/site-packages/flask_cors/extension.py", line 161, in wrapped_function
    return cors_after_request(app.make_response(f(*args, **kwargs)))
  File "/usr/local/lib/python3.6/site-packages/flask/app.py", line 1741, in handle_exception
    reraise(exc_type, exc_value, tb)
  File "/usr/local/lib/python3.6/site-packages/flask/_compat.py", line 35, in reraise
    raise value
  File "/usr/local/lib/python3.6/site-packages/flask/app.py", line 2292, in wsgi_app
    response = self.full_dispatch_request()
  File "/usr/local/lib/python3.6/site-packages/flask/app.py", line 1815, in full_dispatch_request
    rv = self.handle_user_exception(e)
  File "/usr/local/lib/python3.6/site-packages/flask_cors/extension.py", line 161, in wrapped_function
    return cors_after_request(app.make_response(f(*args, **kwargs)))
  File "/usr/local/lib/python3.6/site-packages/flask/app.py", line 1718, in handle_user_exception
    reraise(exc_type, exc_value, tb)
  File "/usr/local/lib/python3.6/site-packages/flask/_compat.py", line 35, in reraise
    raise value
  File "/usr/local/lib/python3.6/site-packages/flask/app.py", line 1813, in full_dispatch_request
    rv = self.dispatch_request()
  File "/usr/local/lib/python3.6/site-packages/flask/app.py", line 1799, in dispatch_request
    return self.view_functions[rule.endpoint](**req.view_args)
  File "/usr/local/lib/python3.6/site-packages/flask_cors/decorator.py", line 128, in wrapped_function
    resp = make_response(f(*args, **kwargs))
  File "/app/app/app.py", line 41, in task_processing_themes_processing
    result = get_similar_tovar(req['text'])
KeyError: 'text'
[2020-02-01 19:19:27 +0000] [18] [ERROR] Error handling request /api/v1/themes/
Traceback (most recent call last):
  File "/usr/local/lib/python3.6/site-packages/gunicorn/workers/base_async.py", line 55, in handle
    self.handle_request(listener_name, req, client, addr)
  File "/usr/local/lib/python3.6/site-packages/gunicorn/workers/ggevent.py", line 143, in handle_request
    super().handle_request(listener_name, req, sock, addr)
  File "/usr/local/lib/python3.6/site-packages/gunicorn/workers/base_async.py", line 106, in handle_request
    respiter = self.wsgi(environ, resp.start_response)
  File "/usr/local/lib/python3.6/site-packages/flask/app.py", line 2309, in __call__
    return self.wsgi_app(environ, start_response)
  File "/usr/local/lib/python3.6/site-packages/flask/app.py", line 2295, in wsgi_app
    response = self.handle_exception(e)
  File "/usr/local/lib/python3.6/site-packages/flask_cors/extension.py", line 161, in wrapped_function
    return cors_after_request(app.make_response(f(*args, **kwargs)))
  File "/usr/local/lib/python3.6/site-packages/flask/app.py", line 1741, in handle_exception
    reraise(exc_type, exc_value, tb)
  File "/usr/local/lib/python3.6/site-packages/flask/_compat.py", line 35, in reraise
    raise value
  File "/usr/local/lib/python3.6/site-packages/flask/app.py", line 2292, in wsgi_app
    response = self.full_dispatch_request()
  File "/usr/local/lib/python3.6/site-packages/flask/app.py", line 1815, in full_dispatch_request
    rv = self.handle_user_exception(e)
  File "/usr/local/lib/python3.6/site-packages/flask_cors/extension.py", line 161, in wrapped_function
    return cors_after_request(app.make_response(f(*args, **kwargs)))
  File "/usr/local/lib/python3.6/site-packages/flask/app.py", line 1718, in handle_user_exception
    reraise(exc_type, exc_value, tb)
  File "/usr/local/lib/python3.6/site-packages/flask/_compat.py", line 35, in reraise
    raise value
  File "/usr/local/lib/python3.6/site-packages/flask/app.py", line 1813, in full_dispatch_request
    rv = self.dispatch_request()
  File "/usr/local/lib/python3.6/site-packages/flask/app.py", line 1799, in dispatch_request
    return self.view_functions[rule.endpoint](**req.view_args)
  File "/usr/local/lib/python3.6/site-packages/flask_cors/decorator.py", line 128, in wrapped_function
    resp = make_response(f(*args, **kwargs))
  File "/app/app/app.py", line 41, in task_processing_themes_processing
    result = get_similar_tovar(req['text'])
KeyError: 'text'
[2020-02-01 19:19:27 +0000] [18] [ERROR] Error handling request /api/v1/themes/
Traceback (most recent call last):
  File "/usr/local/lib/python3.6/site-packages/gunicorn/workers/base_async.py", line 55, in handle
    self.handle_request(listener_name, req, client, addr)
  File "/usr/local/lib/python3.6/site-packages/gunicorn/workers/ggevent.py", line 143, in handle_request
    super().handle_request(listener_name, req, sock, addr)
  File "/usr/local/lib/python3.6/site-packages/gunicorn/workers/base_async.py", line 106, in handle_request
    respiter = self.wsgi(environ, resp.start_response)
  File "/usr/local/lib/python3.6/site-packages/flask/app.py", line 2309, in __call__
    return self.wsgi_app(environ, start_response)
  File "/usr/local/lib/python3.6/site-packages/flask/app.py", line 2295, in wsgi_app
    response = self.handle_exception(e)
  File "/usr/local/lib/python3.6/site-packages/flask_cors/extension.py", line 161, in wrapped_function
    return cors_after_request(app.make_response(f(*args, **kwargs)))
  File "/usr/local/lib/python3.6/site-packages/flask/app.py", line 1741, in handle_exception
    reraise(exc_type, exc_value, tb)
  File "/usr/local/lib/python3.6/site-packages/flask/_compat.py", line 35, in reraise
    raise value
  File "/usr/local/lib/python3.6/site-packages/flask/app.py", line 2292, in wsgi_app
    response = self.full_dispatch_request()
  File "/usr/local/lib/python3.6/site-packages/flask/app.py", line 1815, in full_dispatch_request
    rv = self.handle_user_exception(e)
  File "/usr/local/lib/python3.6/site-packages/flask_cors/extension.py", line 161, in wrapped_function
    return cors_after_request(app.make_response(f(*args, **kwargs)))
  File "/usr/local/lib/python3.6/site-packages/flask/app.py", line 1718, in handle_user_exception
    reraise(exc_type, exc_value, tb)
  File "/usr/local/lib/python3.6/site-packages/flask/_compat.py", line 35, in reraise
    raise value
  File "/usr/local/lib/python3.6/site-packages/flask/app.py", line 1813, in full_dispatch_request
    rv = self.dispatch_request()
  File "/usr/local/lib/python3.6/site-packages/flask/app.py", line 1799, in dispatch_request
    return self.view_functions[rule.endpoint](**req.view_args)
  File "/usr/local/lib/python3.6/site-packages/flask_cors/decorator.py", line 128, in wrapped_function
    resp = make_response(f(*args, **kwargs))
  File "/app/app/app.py", line 41, in task_processing_themes_processing
    result = get_similar_tovar(req['text'])
KeyError: 'text'
[2020-02-01 19:19:27 +0000] [16] [ERROR] Error handling request /api/v1/themes/
Traceback (most recent call last):
  File "/usr/local/lib/python3.6/site-packages/gunicorn/workers/base_async.py", line 55, in handle
    self.handle_request(listener_name, req, client, addr)
  File "/usr/local/lib/python3.6/site-packages/gunicorn/workers/ggevent.py", line 143, in handle_request
    super().handle_request(listener_name, req, sock, addr)
  File "/usr/local/lib/python3.6/site-packages/gunicorn/workers/base_async.py", line 106, in handle_request
    respiter = self.wsgi(environ, resp.start_response)
  File "/usr/local/lib/python3.6/site-packages/flask/app.py", line 2309, in __call__
    return self.wsgi_app(environ, start_response)
  File "/usr/local/lib/python3.6/site-packages/flask/app.py", line 2295, in wsgi_app
    response = self.handle_exception(e)
  File "/usr/local/lib/python3.6/site-packages/flask_cors/extension.py", line 161, in wrapped_function
    return cors_after_request(app.make_response(f(*args, **kwargs)))
  File "/usr/local/lib/python3.6/site-packages/flask/app.py", line 1741, in handle_exception
    reraise(exc_type, exc_value, tb)
  File "/usr/local/lib/python3.6/site-packages/flask/_compat.py", line 35, in reraise
    raise value
  File "/usr/local/lib/python3.6/site-packages/flask/app.py", line 2292, in wsgi_app
    response = self.full_dispatch_request()
  File "/usr/local/lib/python3.6/site-packages/flask/app.py", line 1815, in full_dispatch_request
    rv = self.handle_user_exception(e)
  File "/usr/local/lib/python3.6/site-packages/flask_cors/extension.py", line 161, in wrapped_function
    return cors_after_request(app.make_response(f(*args, **kwargs)))
  File "/usr/local/lib/python3.6/site-packages/flask/app.py", line 1718, in handle_user_exception
    reraise(exc_type, exc_value, tb)
  File "/usr/local/lib/python3.6/site-packages/flask/_compat.py", line 35, in reraise
    raise value
  File "/usr/local/lib/python3.6/site-packages/flask/app.py", line 1813, in full_dispatch_request
    rv = self.dispatch_request()
  File "/usr/local/lib/python3.6/site-packages/flask/app.py", line 1799, in dispatch_request
    return self.view_functions[rule.endpoint](**req.view_args)
  File "/usr/local/lib/python3.6/site-packages/flask_cors/decorator.py", line 128, in wrapped_function
    resp = make_response(f(*args, **kwargs))
  File "/app/app/app.py", line 41, in task_processing_themes_processing
    result = get_similar_tovar(req['text'])
KeyError: 'text'
[2020-02-01 19:19:27 +0000] [17] [ERROR] Error handling request /api/v1/themes/
Traceback (most recent call last):
  File "/usr/local/lib/python3.6/site-packages/gunicorn/workers/base_async.py", line 55, in handle
    self.handle_request(listener_name, req, client, addr)
  File "/usr/local/lib/python3.6/site-packages/gunicorn/workers/ggevent.py", line 143, in handle_request
    super().handle_request(listener_name, req, sock, addr)
  File "/usr/local/lib/python3.6/site-packages/gunicorn/workers/base_async.py", line 106, in handle_request
    respiter = self.wsgi(environ, resp.start_response)
  File "/usr/local/lib/python3.6/site-packages/flask/app.py", line 2309, in __call__
    return self.wsgi_app(environ, start_response)
  File "/usr/local/lib/python3.6/site-packages/flask/app.py", line 2295, in wsgi_app
    response = self.handle_exception(e)
  File "/usr/local/lib/python3.6/site-packages/flask_cors/extension.py", line 161, in wrapped_function
    return cors_after_request(app.make_response(f(*args, **kwargs)))
  File "/usr/local/lib/python3.6/site-packages/flask/app.py", line 1741, in handle_exception
    reraise(exc_type, exc_value, tb)
  File "/usr/local/lib/python3.6/site-packages/flask/_compat.py", line 35, in reraise
    raise value
  File "/usr/local/lib/python3.6/site-packages/flask/app.py", line 2292, in wsgi_app
    response = self.full_dispatch_request()
  File "/usr/local/lib/python3.6/site-packages/flask/app.py", line 1815, in full_dispatch_request
    rv = self.handle_user_exception(e)
  File "/usr/local/lib/python3.6/site-packages/flask_cors/extension.py", line 161, in wrapped_function
    return cors_after_request(app.make_response(f(*args, **kwargs)))
  File "/usr/local/lib/python3.6/site-packages/flask/app.py", line 1718, in handle_user_exception
    reraise(exc_type, exc_value, tb)
  File "/usr/local/lib/python3.6/site-packages/flask/_compat.py", line 35, in reraise
    raise value
  File "/usr/local/lib/python3.6/site-packages/flask/app.py", line 1813, in full_dispatch_request
    rv = self.dispatch_request()
  File "/usr/local/lib/python3.6/site-packages/flask/app.py", line 1799, in dispatch_request
    return self.view_functions[rule.endpoint](**req.view_args)
  File "/usr/local/lib/python3.6/site-packages/flask_cors/decorator.py", line 128, in wrapped_function
    resp = make_response(f(*args, **kwargs))
  File "/app/app/app.py", line 41, in task_processing_themes_processing
    result = get_similar_tovar(req['text'])
KeyError: 'text'
[2020-02-01 19:19:27 +0000] [17] [ERROR] Error handling request /api/v1/themes/
Traceback (most recent call last):
  File "/usr/local/lib/python3.6/site-packages/gunicorn/workers/base_async.py", line 55, in handle
    self.handle_request(listener_name, req, client, addr)
  File "/usr/local/lib/python3.6/site-packages/gunicorn/workers/ggevent.py", line 143, in handle_request
    super().handle_request(listener_name, req, sock, addr)
  File "/usr/local/lib/python3.6/site-packages/gunicorn/workers/base_async.py", line 106, in handle_request
    respiter = self.wsgi(environ, resp.start_response)
  File "/usr/local/lib/python3.6/site-packages/flask/app.py", line 2309, in __call__
    return self.wsgi_app(environ, start_response)
  File "/usr/local/lib/python3.6/site-packages/flask/app.py", line 2295, in wsgi_app
    response = self.handle_exception(e)
  File "/usr/local/lib/python3.6/site-packages/flask_cors/extension.py", line 161, in wrapped_function
    return cors_after_request(app.make_response(f(*args, **kwargs)))
  File "/usr/local/lib/python3.6/site-packages/flask/app.py", line 1741, in handle_exception
    reraise(exc_type, exc_value, tb)
  File "/usr/local/lib/python3.6/site-packages/flask/_compat.py", line 35, in reraise
    raise value
  File "/usr/local/lib/python3.6/site-packages/flask/app.py", line 2292, in wsgi_app
    response = self.full_dispatch_request()
  File "/usr/local/lib/python3.6/site-packages/flask/app.py", line 1815, in full_dispatch_request
    rv = self.handle_user_exception(e)
  File "/usr/local/lib/python3.6/site-packages/flask_cors/extension.py", line 161, in wrapped_function
    return cors_after_request(app.make_response(f(*args, **kwargs)))
  File "/usr/local/lib/python3.6/site-packages/flask/app.py", line 1718, in handle_user_exception
    reraise(exc_type, exc_value, tb)
  File "/usr/local/lib/python3.6/site-packages/flask/_compat.py", line 35, in reraise
    raise value
  File "/usr/local/lib/python3.6/site-packages/flask/app.py", line 1813, in full_dispatch_request
    rv = self.dispatch_request()
  File "/usr/local/lib/python3.6/site-packages/flask/app.py", line 1799, in dispatch_request
    return self.view_functions[rule.endpoint](**req.view_args)
  File "/usr/local/lib/python3.6/site-packages/flask_cors/decorator.py", line 128, in wrapped_function
    resp = make_response(f(*args, **kwargs))
  File "/app/app/app.py", line 41, in task_processing_themes_processing
    result = get_similar_tovar(req['text'])
KeyError: 'text'
[2020-02-01 19:19:27 +0000] [16] [ERROR] Error handling request /api/v1/themes/
Traceback (most recent call last):
  File "/usr/local/lib/python3.6/site-packages/gunicorn/workers/base_async.py", line 55, in handle
    self.handle_request(listener_name, req, client, addr)
  File "/usr/local/lib/python3.6/site-packages/gunicorn/workers/ggevent.py", line 143, in handle_request
    super().handle_request(listener_name, req, sock, addr)
  File "/usr/local/lib/python3.6/site-packages/gunicorn/workers/base_async.py", line 106, in handle_request
    respiter = self.wsgi(environ, resp.start_response)
  File "/usr/local/lib/python3.6/site-packages/flask/app.py", line 2309, in __call__
    return self.wsgi_app(environ, start_response)
  File "/usr/local/lib/python3.6/site-packages/flask/app.py", line 2295, in wsgi_app
    response = self.handle_exception(e)
  File "/usr/local/lib/python3.6/site-packages/flask_cors/extension.py", line 161, in wrapped_function
    return cors_after_request(app.make_response(f(*args, **kwargs)))
  File "/usr/local/lib/python3.6/site-packages/flask/app.py", line 1741, in handle_exception
    reraise(exc_type, exc_value, tb)
  File "/usr/local/lib/python3.6/site-packages/flask/_compat.py", line 35, in reraise
    raise value
  File "/usr/local/lib/python3.6/site-packages/flask/app.py", line 2292, in wsgi_app
    response = self.full_dispatch_request()
  File "/usr/local/lib/python3.6/site-packages/flask/app.py", line 1815, in full_dispatch_request
    rv = self.handle_user_exception(e)
  File "/usr/local/lib/python3.6/site-packages/flask_cors/extension.py", line 161, in wrapped_function
    return cors_after_request(app.make_response(f(*args, **kwargs)))
  File "/usr/local/lib/python3.6/site-packages/flask/app.py", line 1718, in handle_user_exception
    reraise(exc_type, exc_value, tb)
  File "/usr/local/lib/python3.6/site-packages/flask/_compat.py", line 35, in reraise
    raise value
  File "/usr/local/lib/python3.6/site-packages/flask/app.py", line 1813, in full_dispatch_request
    rv = self.dispatch_request()
  File "/usr/local/lib/python3.6/site-packages/flask/app.py", line 1799, in dispatch_request
    return self.view_functions[rule.endpoint](**req.view_args)
  File "/usr/local/lib/python3.6/site-packages/flask_cors/decorator.py", line 128, in wrapped_function
    resp = make_response(f(*args, **kwargs))
  File "/app/app/app.py", line 41, in task_processing_themes_processing
    result = get_similar_tovar(req['text'])
KeyError: 'text'
[2020-02-01 19:19:27 +0000] [18] [ERROR] Error handling request /api/v1/themes/
Traceback (most recent call last):
  File "/usr/local/lib/python3.6/site-packages/gunicorn/workers/base_async.py", line 55, in handle
    self.handle_request(listener_name, req, client, addr)
  File "/usr/local/lib/python3.6/site-packages/gunicorn/workers/ggevent.py", line 143, in handle_request
    super().handle_request(listener_name, req, sock, addr)
  File "/usr/local/lib/python3.6/site-packages/gunicorn/workers/base_async.py", line 106, in handle_request
    respiter = self.wsgi(environ, resp.start_response)
  File "/usr/local/lib/python3.6/site-packages/flask/app.py", line 2309, in __call__
    return self.wsgi_app(environ, start_response)
  File "/usr/local/lib/python3.6/site-packages/flask/app.py", line 2295, in wsgi_app
    response = self.handle_exception(e)
  File "/usr/local/lib/python3.6/site-packages/flask_cors/extension.py", line 161, in wrapped_function
    return cors_after_request(app.make_response(f(*args, **kwargs)))
  File "/usr/local/lib/python3.6/site-packages/flask/app.py", line 1741, in handle_exception
    reraise(exc_type, exc_value, tb)
  File "/usr/local/lib/python3.6/site-packages/flask/_compat.py", line 35, in reraise
    raise value
  File "/usr/local/lib/python3.6/site-packages/flask/app.py", line 2292, in wsgi_app
    response = self.full_dispatch_request()
  File "/usr/local/lib/python3.6/site-packages/flask/app.py", line 1815, in full_dispatch_request
    rv = self.handle_user_exception(e)
  File "/usr/local/lib/python3.6/site-packages/flask_cors/extension.py", line 161, in wrapped_function
    return cors_after_request(app.make_response(f(*args, **kwargs)))
  File "/usr/local/lib/python3.6/site-packages/flask/app.py", line 1718, in handle_user_exception
    reraise(exc_type, exc_value, tb)
  File "/usr/local/lib/python3.6/site-packages/flask/_compat.py", line 35, in reraise
    raise value
  File "/usr/local/lib/python3.6/site-packages/flask/app.py", line 1813, in full_dispatch_request
    rv = self.dispatch_request()
  File "/usr/local/lib/python3.6/site-packages/flask/app.py", line 1799, in dispatch_request
    return self.view_functions[rule.endpoint](**req.view_args)
  File "/usr/local/lib/python3.6/site-packages/flask_cors/decorator.py", line 128, in wrapped_function
    resp = make_response(f(*args, **kwargs))
  File "/app/app/app.py", line 41, in task_processing_themes_processing
    result = get_similar_tovar(req['text'])
KeyError: 'text'
[2020-02-01 19:19:27 +0000] [18] [ERROR] Error handling request /api/v1/themes/
Traceback (most recent call last):
  File "/usr/local/lib/python3.6/site-packages/gunicorn/workers/base_async.py", line 55, in handle
    self.handle_request(listener_name, req, client, addr)
  File "/usr/local/lib/python3.6/site-packages/gunicorn/workers/ggevent.py", line 143, in handle_request
    super().handle_request(listener_name, req, sock, addr)
  File "/usr/local/lib/python3.6/site-packages/gunicorn/workers/base_async.py", line 106, in handle_request
    respiter = self.wsgi(environ, resp.start_response)
  File "/usr/local/lib/python3.6/site-packages/flask/app.py", line 2309, in __call__
    return self.wsgi_app(environ, start_response)
  File "/usr/local/lib/python3.6/site-packages/flask/app.py", line 2295, in wsgi_app
    response = self.handle_exception(e)
  File "/usr/local/lib/python3.6/site-packages/flask_cors/extension.py", line 161, in wrapped_function
    return cors_after_request(app.make_response(f(*args, **kwargs)))
  File "/usr/local/lib/python3.6/site-packages/flask/app.py", line 1741, in handle_exception
    reraise(exc_type, exc_value, tb)
  File "/usr/local/lib/python3.6/site-packages/flask/_compat.py", line 35, in reraise
    raise value
  File "/usr/local/lib/python3.6/site-packages/flask/app.py", line 2292, in wsgi_app
    response = self.full_dispatch_request()
  File "/usr/local/lib/python3.6/site-packages/flask/app.py", line 1815, in full_dispatch_request
    rv = self.handle_user_exception(e)
  File "/usr/local/lib/python3.6/site-packages/flask_cors/extension.py", line 161, in wrapped_function
    return cors_after_request(app.make_response(f(*args, **kwargs)))
  File "/usr/local/lib/python3.6/site-packages/flask/app.py", line 1718, in handle_user_exception
    reraise(exc_type, exc_value, tb)
  File "/usr/local/lib/python3.6/site-packages/flask/_compat.py", line 35, in reraise
    raise value
  File "/usr/local/lib/python3.6/site-packages/flask/app.py", line 1813, in full_dispatch_request
    rv = self.dispatch_request()
  File "/usr/local/lib/python3.6/site-packages/flask/app.py", line 1799, in dispatch_request
    return self.view_functions[rule.endpoint](**req.view_args)
  File "/usr/local/lib/python3.6/site-packages/flask_cors/decorator.py", line 128, in wrapped_function
    resp = make_response(f(*args, **kwargs))
  File "/app/app/app.py", line 41, in task_processing_themes_processing
    result = get_similar_tovar(req['text'])
KeyError: 'text'
[2020-02-01 19:19:27 +0000] [18] [ERROR] Error handling request /api/v1/themes/
Traceback (most recent call last):
  File "/usr/local/lib/python3.6/site-packages/gunicorn/workers/base_async.py", line 55, in handle
    self.handle_request(listener_name, req, client, addr)
  File "/usr/local/lib/python3.6/site-packages/gunicorn/workers/ggevent.py", line 143, in handle_request
    super().handle_request(listener_name, req, sock, addr)
  File "/usr/local/lib/python3.6/site-packages/gunicorn/workers/base_async.py", line 106, in handle_request
    respiter = self.wsgi(environ, resp.start_response)
  File "/usr/local/lib/python3.6/site-packages/flask/app.py", line 2309, in __call__
    return self.wsgi_app(environ, start_response)
  File "/usr/local/lib/python3.6/site-packages/flask/app.py", line 2295, in wsgi_app
    response = self.handle_exception(e)
  File "/usr/local/lib/python3.6/site-packages/flask_cors/extension.py", line 161, in wrapped_function
    return cors_after_request(app.make_response(f(*args, **kwargs)))
  File "/usr/local/lib/python3.6/site-packages/flask/app.py", line 1741, in handle_exception
    reraise(exc_type, exc_value, tb)
  File "/usr/local/lib/python3.6/site-packages/flask/_compat.py", line 35, in reraise
    raise value
  File "/usr/local/lib/python3.6/site-packages/flask/app.py", line 2292, in wsgi_app
    response = self.full_dispatch_request()
  File "/usr/local/lib/python3.6/site-packages/flask/app.py", line 1815, in full_dispatch_request
    rv = self.handle_user_exception(e)
  File "/usr/local/lib/python3.6/site-packages/flask_cors/extension.py", line 161, in wrapped_function
    return cors_after_request(app.make_response(f(*args, **kwargs)))
  File "/usr/local/lib/python3.6/site-packages/flask/app.py", line 1718, in handle_user_exception
    reraise(exc_type, exc_value, tb)
  File "/usr/local/lib/python3.6/site-packages/flask/_compat.py", line 35, in reraise
    raise value
  File "/usr/local/lib/python3.6/site-packages/flask/app.py", line 1813, in full_dispatch_request
    rv = self.dispatch_request()
  File "/usr/local/lib/python3.6/site-packages/flask/app.py", line 1799, in dispatch_request
    return self.view_functions[rule.endpoint](**req.view_args)
  File "/usr/local/lib/python3.6/site-packages/flask_cors/decorator.py", line 128, in wrapped_function
    resp = make_response(f(*args, **kwargs))
  File "/app/app/app.py", line 41, in task_processing_themes_processing
    result = get_similar_tovar(req['text'])
KeyError: 'text'
[2020-02-01 19:19:27 +0000] [16] [ERROR] Error handling request /api/v1/themes/
Traceback (most recent call last):
  File "/usr/local/lib/python3.6/site-packages/gunicorn/workers/base_async.py", line 55, in handle
    self.handle_request(listener_name, req, client, addr)
  File "/usr/local/lib/python3.6/site-packages/gunicorn/workers/ggevent.py", line 143, in handle_request
    super().handle_request(listener_name, req, sock, addr)
  File "/usr/local/lib/python3.6/site-packages/gunicorn/workers/base_async.py", line 106, in handle_request
    respiter = self.wsgi(environ, resp.start_response)
  File "/usr/local/lib/python3.6/site-packages/flask/app.py", line 2309, in __call__
    return self.wsgi_app(environ, start_response)
  File "/usr/local/lib/python3.6/site-packages/flask/app.py", line 2295, in wsgi_app
    response = self.handle_exception(e)
  File "/usr/local/lib/python3.6/site-packages/flask_cors/extension.py", line 161, in wrapped_function
    return cors_after_request(app.make_response(f(*args, **kwargs)))
  File "/usr/local/lib/python3.6/site-packages/flask/app.py", line 1741, in handle_exception
    reraise(exc_type, exc_value, tb)
  File "/usr/local/lib/python3.6/site-packages/flask/_compat.py", line 35, in reraise
    raise value
  File "/usr/local/lib/python3.6/site-packages/flask/app.py", line 2292, in wsgi_app
    response = self.full_dispatch_request()
  File "/usr/local/lib/python3.6/site-packages/flask/app.py", line 1815, in full_dispatch_request
    rv = self.handle_user_exception(e)
  File "/usr/local/lib/python3.6/site-packages/flask_cors/extension.py", line 161, in wrapped_function
    return cors_after_request(app.make_response(f(*args, **kwargs)))
  File "/usr/local/lib/python3.6/site-packages/flask/app.py", line 1718, in handle_user_exception
    reraise(exc_type, exc_value, tb)
  File "/usr/local/lib/python3.6/site-packages/flask/_compat.py", line 35, in reraise
    raise value
  File "/usr/local/lib/python3.6/site-packages/flask/app.py", line 1813, in full_dispatch_request
    rv = self.dispatch_request()
  File "/usr/local/lib/python3.6/site-packages/flask/app.py", line 1799, in dispatch_request
    return self.view_functions[rule.endpoint](**req.view_args)
  File "/usr/local/lib/python3.6/site-packages/flask_cors/decorator.py", line 128, in wrapped_function
    resp = make_response(f(*args, **kwargs))
  File "/app/app/app.py", line 41, in task_processing_themes_processing
    result = get_similar_tovar(req['text'])
KeyError: 'text'
[2020-02-01 19:19:27 +0000] [17] [ERROR] Error handling request /api/v1/themes/
Traceback (most recent call last):
  File "/usr/local/lib/python3.6/site-packages/gunicorn/workers/base_async.py", line 55, in handle
    self.handle_request(listener_name, req, client, addr)
  File "/usr/local/lib/python3.6/site-packages/gunicorn/workers/ggevent.py", line 143, in handle_request
    super().handle_request(listener_name, req, sock, addr)
  File "/usr/local/lib/python3.6/site-packages/gunicorn/workers/base_async.py", line 106, in handle_request
    respiter = self.wsgi(environ, resp.start_response)
  File "/usr/local/lib/python3.6/site-packages/flask/app.py", line 2309, in __call__
    return self.wsgi_app(environ, start_response)
  File "/usr/local/lib/python3.6/site-packages/flask/app.py", line 2295, in wsgi_app
    response = self.handle_exception(e)
  File "/usr/local/lib/python3.6/site-packages/flask_cors/extension.py", line 161, in wrapped_function
    return cors_after_request(app.make_response(f(*args, **kwargs)))
  File "/usr/local/lib/python3.6/site-packages/flask/app.py", line 1741, in handle_exception
    reraise(exc_type, exc_value, tb)
  File "/usr/local/lib/python3.6/site-packages/flask/_compat.py", line 35, in reraise
    raise value
  File "/usr/local/lib/python3.6/site-packages/flask/app.py", line 2292, in wsgi_app
    response = self.full_dispatch_request()
  File "/usr/local/lib/python3.6/site-packages/flask/app.py", line 1815, in full_dispatch_request
    rv = self.handle_user_exception(e)
  File "/usr/local/lib/python3.6/site-packages/flask_cors/extension.py", line 161, in wrapped_function
    return cors_after_request(app.make_response(f(*args, **kwargs)))
  File "/usr/local/lib/python3.6/site-packages/flask/app.py", line 1718, in handle_user_exception
    reraise(exc_type, exc_value, tb)
  File "/usr/local/lib/python3.6/site-packages/flask/_compat.py", line 35, in reraise
    raise value
  File "/usr/local/lib/python3.6/site-packages/flask/app.py", line 1813, in full_dispatch_request
    rv = self.dispatch_request()
  File "/usr/local/lib/python3.6/site-packages/flask/app.py", line 1799, in dispatch_request
    return self.view_functions[rule.endpoint](**req.view_args)
  File "/usr/local/lib/python3.6/site-packages/flask_cors/decorator.py", line 128, in wrapped_function
    resp = make_response(f(*args, **kwargs))
  File "/app/app/app.py", line 41, in task_processing_themes_processing
    result = get_similar_tovar(req['text'])
KeyError: 'text'
[2020-02-01 19:19:27 +0000] [18] [ERROR] Error handling request /api/v1/themes/
Traceback (most recent call last):
  File "/usr/local/lib/python3.6/site-packages/gunicorn/workers/base_async.py", line 55, in handle
    self.handle_request(listener_name, req, client, addr)
  File "/usr/local/lib/python3.6/site-packages/gunicorn/workers/ggevent.py", line 143, in handle_request
    super().handle_request(listener_name, req, sock, addr)
  File "/usr/local/lib/python3.6/site-packages/gunicorn/workers/base_async.py", line 106, in handle_request
    respiter = self.wsgi(environ, resp.start_response)
  File "/usr/local/lib/python3.6/site-packages/flask/app.py", line 2309, in __call__
    return self.wsgi_app(environ, start_response)
  File "/usr/local/lib/python3.6/site-packages/flask/app.py", line 2295, in wsgi_app
    response = self.handle_exception(e)
  File "/usr/local/lib/python3.6/site-packages/flask_cors/extension.py", line 161, in wrapped_function
    return cors_after_request(app.make_response(f(*args, **kwargs)))
  File "/usr/local/lib/python3.6/site-packages/flask/app.py", line 1741, in handle_exception
    reraise(exc_type, exc_value, tb)
  File "/usr/local/lib/python3.6/site-packages/flask/_compat.py", line 35, in reraise
    raise value
  File "/usr/local/lib/python3.6/site-packages/flask/app.py", line 2292, in wsgi_app
    response = self.full_dispatch_request()
  File "/usr/local/lib/python3.6/site-packages/flask/app.py", line 1815, in full_dispatch_request
    rv = self.handle_user_exception(e)
  File "/usr/local/lib/python3.6/site-packages/flask_cors/extension.py", line 161, in wrapped_function
    return cors_after_request(app.make_response(f(*args, **kwargs)))
  File "/usr/local/lib/python3.6/site-packages/flask/app.py", line 1718, in handle_user_exception
    reraise(exc_type, exc_value, tb)
  File "/usr/local/lib/python3.6/site-packages/flask/_compat.py", line 35, in reraise
    raise value
  File "/usr/local/lib/python3.6/site-packages/flask/app.py", line 1813, in full_dispatch_request
    rv = self.dispatch_request()
  File "/usr/local/lib/python3.6/site-packages/flask/app.py", line 1799, in dispatch_request
    return self.view_functions[rule.endpoint](**req.view_args)
  File "/usr/local/lib/python3.6/site-packages/flask_cors/decorator.py", line 128, in wrapped_function
    resp = make_response(f(*args, **kwargs))
  File "/app/app/app.py", line 41, in task_processing_themes_processing
    result = get_similar_tovar(req['text'])
KeyError: 'text'
[2020-02-01 19:19:27 +0000] [17] [ERROR] Error handling request /api/v1/themes/
Traceback (most recent call last):
  File "/usr/local/lib/python3.6/site-packages/gunicorn/workers/base_async.py", line 55, in handle
    self.handle_request(listener_name, req, client, addr)
  File "/usr/local/lib/python3.6/site-packages/gunicorn/workers/ggevent.py", line 143, in handle_request
    super().handle_request(listener_name, req, sock, addr)
  File "/usr/local/lib/python3.6/site-packages/gunicorn/workers/base_async.py", line 106, in handle_request
    respiter = self.wsgi(environ, resp.start_response)
  File "/usr/local/lib/python3.6/site-packages/flask/app.py", line 2309, in __call__
    return self.wsgi_app(environ, start_response)
  File "/usr/local/lib/python3.6/site-packages/flask/app.py", line 2295, in wsgi_app
    response = self.handle_exception(e)
  File "/usr/local/lib/python3.6/site-packages/flask_cors/extension.py", line 161, in wrapped_function
    return cors_after_request(app.make_response(f(*args, **kwargs)))
  File "/usr/local/lib/python3.6/site-packages/flask/app.py", line 1741, in handle_exception
    reraise(exc_type, exc_value, tb)
  File "/usr/local/lib/python3.6/site-packages/flask/_compat.py", line 35, in reraise
    raise value
  File "/usr/local/lib/python3.6/site-packages/flask/app.py", line 2292, in wsgi_app
    response = self.full_dispatch_request()
  File "/usr/local/lib/python3.6/site-packages/flask/app.py", line 1815, in full_dispatch_request
    rv = self.handle_user_exception(e)
  File "/usr/local/lib/python3.6/site-packages/flask_cors/extension.py", line 161, in wrapped_function
    return cors_after_request(app.make_response(f(*args, **kwargs)))
  File "/usr/local/lib/python3.6/site-packages/flask/app.py", line 1718, in handle_user_exception
    reraise(exc_type, exc_value, tb)
  File "/usr/local/lib/python3.6/site-packages/flask/_compat.py", line 35, in reraise
    raise value
  File "/usr/local/lib/python3.6/site-packages/flask/app.py", line 1813, in full_dispatch_request
    rv = self.dispatch_request()
  File "/usr/local/lib/python3.6/site-packages/flask/app.py", line 1799, in dispatch_request
    return self.view_functions[rule.endpoint](**req.view_args)
  File "/usr/local/lib/python3.6/site-packages/flask_cors/decorator.py", line 128, in wrapped_function
    resp = make_response(f(*args, **kwargs))
  File "/app/app/app.py", line 41, in task_processing_themes_processing
    result = get_similar_tovar(req['text'])
KeyError: 'text'
[2020-02-01 19:19:27 +0000] [17] [ERROR] Error handling request /api/v1/themes/
Traceback (most recent call last):
  File "/usr/local/lib/python3.6/site-packages/gunicorn/workers/base_async.py", line 55, in handle
    self.handle_request(listener_name, req, client, addr)
  File "/usr/local/lib/python3.6/site-packages/gunicorn/workers/ggevent.py", line 143, in handle_request
    super().handle_request(listener_name, req, sock, addr)
  File "/usr/local/lib/python3.6/site-packages/gunicorn/workers/base_async.py", line 106, in handle_request
    respiter = self.wsgi(environ, resp.start_response)
  File "/usr/local/lib/python3.6/site-packages/flask/app.py", line 2309, in __call__
    return self.wsgi_app(environ, start_response)
  File "/usr/local/lib/python3.6/site-packages/flask/app.py", line 2295, in wsgi_app
    response = self.handle_exception(e)
  File "/usr/local/lib/python3.6/site-packages/flask_cors/extension.py", line 161, in wrapped_function
    return cors_after_request(app.make_response(f(*args, **kwargs)))
  File "/usr/local/lib/python3.6/site-packages/flask/app.py", line 1741, in handle_exception
    reraise(exc_type, exc_value, tb)
  File "/usr/local/lib/python3.6/site-packages/flask/_compat.py", line 35, in reraise
    raise value
  File "/usr/local/lib/python3.6/site-packages/flask/app.py", line 2292, in wsgi_app
    response = self.full_dispatch_request()
  File "/usr/local/lib/python3.6/site-packages/flask/app.py", line 1815, in full_dispatch_request
    rv = self.handle_user_exception(e)
  File "/usr/local/lib/python3.6/site-packages/flask_cors/extension.py", line 161, in wrapped_function
    return cors_after_request(app.make_response(f(*args, **kwargs)))
  File "/usr/local/lib/python3.6/site-packages/flask/app.py", line 1718, in handle_user_exception
    reraise(exc_type, exc_value, tb)
  File "/usr/local/lib/python3.6/site-packages/flask/_compat.py", line 35, in reraise
    raise value
  File "/usr/local/lib/python3.6/site-packages/flask/app.py", line 1813, in full_dispatch_request
    rv = self.dispatch_request()
  File "/usr/local/lib/python3.6/site-packages/flask/app.py", line 1799, in dispatch_request
    return self.view_functions[rule.endpoint](**req.view_args)
  File "/usr/local/lib/python3.6/site-packages/flask_cors/decorator.py", line 128, in wrapped_function
    resp = make_response(f(*args, **kwargs))
  File "/app/app/app.py", line 41, in task_processing_themes_processing
    result = get_similar_tovar(req['text'])
KeyError: 'text'
[2020-02-01 19:19:27 +0000] [18] [ERROR] Error handling request /api/v1/themes/
Traceback (most recent call last):
  File "/usr/local/lib/python3.6/site-packages/gunicorn/workers/base_async.py", line 55, in handle
    self.handle_request(listener_name, req, client, addr)
  File "/usr/local/lib/python3.6/site-packages/gunicorn/workers/ggevent.py", line 143, in handle_request
    super().handle_request(listener_name, req, sock, addr)
  File "/usr/local/lib/python3.6/site-packages/gunicorn/workers/base_async.py", line 106, in handle_request
    respiter = self.wsgi(environ, resp.start_response)
  File "/usr/local/lib/python3.6/site-packages/flask/app.py", line 2309, in __call__
    return self.wsgi_app(environ, start_response)
  File "/usr/local/lib/python3.6/site-packages/flask/app.py", line 2295, in wsgi_app
    response = self.handle_exception(e)
  File "/usr/local/lib/python3.6/site-packages/flask_cors/extension.py", line 161, in wrapped_function
    return cors_after_request(app.make_response(f(*args, **kwargs)))
  File "/usr/local/lib/python3.6/site-packages/flask/app.py", line 1741, in handle_exception
    reraise(exc_type, exc_value, tb)
  File "/usr/local/lib/python3.6/site-packages/flask/_compat.py", line 35, in reraise
    raise value
  File "/usr/local/lib/python3.6/site-packages/flask/app.py", line 2292, in wsgi_app
    response = self.full_dispatch_request()
  File "/usr/local/lib/python3.6/site-packages/flask/app.py", line 1815, in full_dispatch_request
    rv = self.handle_user_exception(e)
  File "/usr/local/lib/python3.6/site-packages/flask_cors/extension.py", line 161, in wrapped_function
    return cors_after_request(app.make_response(f(*args, **kwargs)))
  File "/usr/local/lib/python3.6/site-packages/flask/app.py", line 1718, in handle_user_exception
    reraise(exc_type, exc_value, tb)
  File "/usr/local/lib/python3.6/site-packages/flask/_compat.py", line 35, in reraise
    raise value
  File "/usr/local/lib/python3.6/site-packages/flask/app.py", line 1813, in full_dispatch_request
    rv = self.dispatch_request()
  File "/usr/local/lib/python3.6/site-packages/flask/app.py", line 1799, in dispatch_request
    return self.view_functions[rule.endpoint](**req.view_args)
  File "/usr/local/lib/python3.6/site-packages/flask_cors/decorator.py", line 128, in wrapped_function
    resp = make_response(f(*args, **kwargs))
  File "/app/app/app.py", line 41, in task_processing_themes_processing
    result = get_similar_tovar(req['text'])
KeyError: 'text'
[2020-02-01 19:19:27 +0000] [17] [ERROR] Error handling request /api/v1/themes/
Traceback (most recent call last):
  File "/usr/local/lib/python3.6/site-packages/gunicorn/workers/base_async.py", line 55, in handle
    self.handle_request(listener_name, req, client, addr)
  File "/usr/local/lib/python3.6/site-packages/gunicorn/workers/ggevent.py", line 143, in handle_request
    super().handle_request(listener_name, req, sock, addr)
  File "/usr/local/lib/python3.6/site-packages/gunicorn/workers/base_async.py", line 106, in handle_request
    respiter = self.wsgi(environ, resp.start_response)
  File "/usr/local/lib/python3.6/site-packages/flask/app.py", line 2309, in __call__
    return self.wsgi_app(environ, start_response)
  File "/usr/local/lib/python3.6/site-packages/flask/app.py", line 2295, in wsgi_app
    response = self.handle_exception(e)
  File "/usr/local/lib/python3.6/site-packages/flask_cors/extension.py", line 161, in wrapped_function
    return cors_after_request(app.make_response(f(*args, **kwargs)))
  File "/usr/local/lib/python3.6/site-packages/flask/app.py", line 1741, in handle_exception
    reraise(exc_type, exc_value, tb)
  File "/usr/local/lib/python3.6/site-packages/flask/_compat.py", line 35, in reraise
    raise value
  File "/usr/local/lib/python3.6/site-packages/flask/app.py", line 2292, in wsgi_app
    response = self.full_dispatch_request()
  File "/usr/local/lib/python3.6/site-packages/flask/app.py", line 1815, in full_dispatch_request
    rv = self.handle_user_exception(e)
  File "/usr/local/lib/python3.6/site-packages/flask_cors/extension.py", line 161, in wrapped_function
    return cors_after_request(app.make_response(f(*args, **kwargs)))
  File "/usr/local/lib/python3.6/site-packages/flask/app.py", line 1718, in handle_user_exception
    reraise(exc_type, exc_value, tb)
  File "/usr/local/lib/python3.6/site-packages/flask/_compat.py", line 35, in reraise
    raise value
  File "/usr/local/lib/python3.6/site-packages/flask/app.py", line 1813, in full_dispatch_request
    rv = self.dispatch_request()
  File "/usr/local/lib/python3.6/site-packages/flask/app.py", line 1799, in dispatch_request
    return self.view_functions[rule.endpoint](**req.view_args)
  File "/usr/local/lib/python3.6/site-packages/flask_cors/decorator.py", line 128, in wrapped_function
    resp = make_response(f(*args, **kwargs))
  File "/app/app/app.py", line 41, in task_processing_themes_processing
    result = get_similar_tovar(req['text'])
KeyError: 'text'
[2020-02-01 19:19:27 +0000] [16] [ERROR] Error handling request /api/v1/themes/
Traceback (most recent call last):
  File "/usr/local/lib/python3.6/site-packages/gunicorn/workers/base_async.py", line 55, in handle
    self.handle_request(listener_name, req, client, addr)
  File "/usr/local/lib/python3.6/site-packages/gunicorn/workers/ggevent.py", line 143, in handle_request
    super().handle_request(listener_name, req, sock, addr)
  File "/usr/local/lib/python3.6/site-packages/gunicorn/workers/base_async.py", line 106, in handle_request
    respiter = self.wsgi(environ, resp.start_response)
  File "/usr/local/lib/python3.6/site-packages/flask/app.py", line 2309, in __call__
    return self.wsgi_app(environ, start_response)
  File "/usr/local/lib/python3.6/site-packages/flask/app.py", line 2295, in wsgi_app
    response = self.handle_exception(e)
  File "/usr/local/lib/python3.6/site-packages/flask_cors/extension.py", line 161, in wrapped_function
    return cors_after_request(app.make_response(f(*args, **kwargs)))
  File "/usr/local/lib/python3.6/site-packages/flask/app.py", line 1741, in handle_exception
    reraise(exc_type, exc_value, tb)
  File "/usr/local/lib/python3.6/site-packages/flask/_compat.py", line 35, in reraise
    raise value
  File "/usr/local/lib/python3.6/site-packages/flask/app.py", line 2292, in wsgi_app
    response = self.full_dispatch_request()
  File "/usr/local/lib/python3.6/site-packages/flask/app.py", line 1815, in full_dispatch_request
    rv = self.handle_user_exception(e)
  File "/usr/local/lib/python3.6/site-packages/flask_cors/extension.py", line 161, in wrapped_function
    return cors_after_request(app.make_response(f(*args, **kwargs)))
  File "/usr/local/lib/python3.6/site-packages/flask/app.py", line 1718, in handle_user_exception
    reraise(exc_type, exc_value, tb)
  File "/usr/local/lib/python3.6/site-packages/flask/_compat.py", line 35, in reraise
    raise value
  File "/usr/local/lib/python3.6/site-packages/flask/app.py", line 1813, in full_dispatch_request
    rv = self.dispatch_request()
  File "/usr/local/lib/python3.6/site-packages/flask/app.py", line 1799, in dispatch_request
    return self.view_functions[rule.endpoint](**req.view_args)
  File "/usr/local/lib/python3.6/site-packages/flask_cors/decorator.py", line 128, in wrapped_function
    resp = make_response(f(*args, **kwargs))
  File "/app/app/app.py", line 41, in task_processing_themes_processing
    result = get_similar_tovar(req['text'])
KeyError: 'text'
[2020-02-01 19:19:27 +0000] [17] [ERROR] Error handling request /api/v1/themes/
Traceback (most recent call last):
  File "/usr/local/lib/python3.6/site-packages/gunicorn/workers/base_async.py", line 55, in handle
    self.handle_request(listener_name, req, client, addr)
  File "/usr/local/lib/python3.6/site-packages/gunicorn/workers/ggevent.py", line 143, in handle_request
    super().handle_request(listener_name, req, sock, addr)
  File "/usr/local/lib/python3.6/site-packages/gunicorn/workers/base_async.py", line 106, in handle_request
    respiter = self.wsgi(environ, resp.start_response)
  File "/usr/local/lib/python3.6/site-packages/flask/app.py", line 2309, in __call__
    return self.wsgi_app(environ, start_response)
  File "/usr/local/lib/python3.6/site-packages/flask/app.py", line 2295, in wsgi_app
    response = self.handle_exception(e)
  File "/usr/local/lib/python3.6/site-packages/flask_cors/extension.py", line 161, in wrapped_function
    return cors_after_request(app.make_response(f(*args, **kwargs)))
  File "/usr/local/lib/python3.6/site-packages/flask/app.py", line 1741, in handle_exception
    reraise(exc_type, exc_value, tb)
  File "/usr/local/lib/python3.6/site-packages/flask/_compat.py", line 35, in reraise
    raise value
  File "/usr/local/lib/python3.6/site-packages/flask/app.py", line 2292, in wsgi_app
    response = self.full_dispatch_request()
  File "/usr/local/lib/python3.6/site-packages/flask/app.py", line 1815, in full_dispatch_request
    rv = self.handle_user_exception(e)
  File "/usr/local/lib/python3.6/site-packages/flask_cors/extension.py", line 161, in wrapped_function
    return cors_after_request(app.make_response(f(*args, **kwargs)))
  File "/usr/local/lib/python3.6/site-packages/flask/app.py", line 1718, in handle_user_exception
    reraise(exc_type, exc_value, tb)
  File "/usr/local/lib/python3.6/site-packages/flask/_compat.py", line 35, in reraise
    raise value
  File "/usr/local/lib/python3.6/site-packages/flask/app.py", line 1813, in full_dispatch_request
    rv = self.dispatch_request()
  File "/usr/local/lib/python3.6/site-packages/flask/app.py", line 1799, in dispatch_request
    return self.view_functions[rule.endpoint](**req.view_args)
  File "/usr/local/lib/python3.6/site-packages/flask_cors/decorator.py", line 128, in wrapped_function
    resp = make_response(f(*args, **kwargs))
  File "/app/app/app.py", line 41, in task_processing_themes_processing
    result = get_similar_tovar(req['text'])
KeyError: 'text'
[2020-02-01 19:19:28 +0000] [18] [ERROR] Error handling request /api/v1/themes/
Traceback (most recent call last):
  File "/usr/local/lib/python3.6/site-packages/gunicorn/workers/base_async.py", line 55, in handle
    self.handle_request(listener_name, req, client, addr)
  File "/usr/local/lib/python3.6/site-packages/gunicorn/workers/ggevent.py", line 143, in handle_request
    super().handle_request(listener_name, req, sock, addr)
  File "/usr/local/lib/python3.6/site-packages/gunicorn/workers/base_async.py", line 106, in handle_request
    respiter = self.wsgi(environ, resp.start_response)
  File "/usr/local/lib/python3.6/site-packages/flask/app.py", line 2309, in __call__
    return self.wsgi_app(environ, start_response)
  File "/usr/local/lib/python3.6/site-packages/flask/app.py", line 2295, in wsgi_app
    response = self.handle_exception(e)
  File "/usr/local/lib/python3.6/site-packages/flask_cors/extension.py", line 161, in wrapped_function
    return cors_after_request(app.make_response(f(*args, **kwargs)))
  File "/usr/local/lib/python3.6/site-packages/flask/app.py", line 1741, in handle_exception
    reraise(exc_type, exc_value, tb)
  File "/usr/local/lib/python3.6/site-packages/flask/_compat.py", line 35, in reraise
    raise value
  File "/usr/local/lib/python3.6/site-packages/flask/app.py", line 2292, in wsgi_app
    response = self.full_dispatch_request()
  File "/usr/local/lib/python3.6/site-packages/flask/app.py", line 1815, in full_dispatch_request
    rv = self.handle_user_exception(e)
  File "/usr/local/lib/python3.6/site-packages/flask_cors/extension.py", line 161, in wrapped_function
    return cors_after_request(app.make_response(f(*args, **kwargs)))
  File "/usr/local/lib/python3.6/site-packages/flask/app.py", line 1718, in handle_user_exception
    reraise(exc_type, exc_value, tb)
  File "/usr/local/lib/python3.6/site-packages/flask/_compat.py", line 35, in reraise
    raise value
  File "/usr/local/lib/python3.6/site-packages/flask/app.py", line 1813, in full_dispatch_request
    rv = self.dispatch_request()
  File "/usr/local/lib/python3.6/site-packages/flask/app.py", line 1799, in dispatch_request
    return self.view_functions[rule.endpoint](**req.view_args)
  File "/usr/local/lib/python3.6/site-packages/flask_cors/decorator.py", line 128, in wrapped_function
    resp = make_response(f(*args, **kwargs))
  File "/app/app/app.py", line 41, in task_processing_themes_processing
    result = get_similar_tovar(req['text'])
KeyError: 'text'
[2020-02-01 19:19:28 +0000] [17] [ERROR] Error handling request /api/v1/themes/
Traceback (most recent call last):
  File "/usr/local/lib/python3.6/site-packages/gunicorn/workers/base_async.py", line 55, in handle
    self.handle_request(listener_name, req, client, addr)
  File "/usr/local/lib/python3.6/site-packages/gunicorn/workers/ggevent.py", line 143, in handle_request
    super().handle_request(listener_name, req, sock, addr)
  File "/usr/local/lib/python3.6/site-packages/gunicorn/workers/base_async.py", line 106, in handle_request
    respiter = self.wsgi(environ, resp.start_response)
  File "/usr/local/lib/python3.6/site-packages/flask/app.py", line 2309, in __call__
    return self.wsgi_app(environ, start_response)
  File "/usr/local/lib/python3.6/site-packages/flask/app.py", line 2295, in wsgi_app
    response = self.handle_exception(e)
  File "/usr/local/lib/python3.6/site-packages/flask_cors/extension.py", line 161, in wrapped_function
    return cors_after_request(app.make_response(f(*args, **kwargs)))
  File "/usr/local/lib/python3.6/site-packages/flask/app.py", line 1741, in handle_exception
    reraise(exc_type, exc_value, tb)
  File "/usr/local/lib/python3.6/site-packages/flask/_compat.py", line 35, in reraise
    raise value
  File "/usr/local/lib/python3.6/site-packages/flask/app.py", line 2292, in wsgi_app
    response = self.full_dispatch_request()
  File "/usr/local/lib/python3.6/site-packages/flask/app.py", line 1815, in full_dispatch_request
    rv = self.handle_user_exception(e)
  File "/usr/local/lib/python3.6/site-packages/flask_cors/extension.py", line 161, in wrapped_function
    return cors_after_request(app.make_response(f(*args, **kwargs)))
  File "/usr/local/lib/python3.6/site-packages/flask/app.py", line 1718, in handle_user_exception
    reraise(exc_type, exc_value, tb)
  File "/usr/local/lib/python3.6/site-packages/flask/_compat.py", line 35, in reraise
    raise value
  File "/usr/local/lib/python3.6/site-packages/flask/app.py", line 1813, in full_dispatch_request
    rv = self.dispatch_request()
  File "/usr/local/lib/python3.6/site-packages/flask/app.py", line 1799, in dispatch_request
    return self.view_functions[rule.endpoint](**req.view_args)
  File "/usr/local/lib/python3.6/site-packages/flask_cors/decorator.py", line 128, in wrapped_function
    resp = make_response(f(*args, **kwargs))
  File "/app/app/app.py", line 41, in task_processing_themes_processing
    result = get_similar_tovar(req['text'])
KeyError: 'text'
[2020-02-01 19:19:28 +0000] [18] [ERROR] Error handling request /api/v1/themes/
Traceback (most recent call last):
  File "/usr/local/lib/python3.6/site-packages/gunicorn/workers/base_async.py", line 55, in handle
    self.handle_request(listener_name, req, client, addr)
  File "/usr/local/lib/python3.6/site-packages/gunicorn/workers/ggevent.py", line 143, in handle_request
    super().handle_request(listener_name, req, sock, addr)
  File "/usr/local/lib/python3.6/site-packages/gunicorn/workers/base_async.py", line 106, in handle_request
    respiter = self.wsgi(environ, resp.start_response)
  File "/usr/local/lib/python3.6/site-packages/flask/app.py", line 2309, in __call__
    return self.wsgi_app(environ, start_response)
  File "/usr/local/lib/python3.6/site-packages/flask/app.py", line 2295, in wsgi_app
    response = self.handle_exception(e)
  File "/usr/local/lib/python3.6/site-packages/flask_cors/extension.py", line 161, in wrapped_function
    return cors_after_request(app.make_response(f(*args, **kwargs)))
  File "/usr/local/lib/python3.6/site-packages/flask/app.py", line 1741, in handle_exception
    reraise(exc_type, exc_value, tb)
  File "/usr/local/lib/python3.6/site-packages/flask/_compat.py", line 35, in reraise
    raise value
  File "/usr/local/lib/python3.6/site-packages/flask/app.py", line 2292, in wsgi_app
    response = self.full_dispatch_request()
  File "/usr/local/lib/python3.6/site-packages/flask/app.py", line 1815, in full_dispatch_request
    rv = self.handle_user_exception(e)
  File "/usr/local/lib/python3.6/site-packages/flask_cors/extension.py", line 161, in wrapped_function
    return cors_after_request(app.make_response(f(*args, **kwargs)))
  File "/usr/local/lib/python3.6/site-packages/flask/app.py", line 1718, in handle_user_exception
    reraise(exc_type, exc_value, tb)
  File "/usr/local/lib/python3.6/site-packages/flask/_compat.py", line 35, in reraise
    raise value
  File "/usr/local/lib/python3.6/site-packages/flask/app.py", line 1813, in full_dispatch_request
    rv = self.dispatch_request()
  File "/usr/local/lib/python3.6/site-packages/flask/app.py", line 1799, in dispatch_request
    return self.view_functions[rule.endpoint](**req.view_args)
  File "/usr/local/lib/python3.6/site-packages/flask_cors/decorator.py", line 128, in wrapped_function
    resp = make_response(f(*args, **kwargs))
  File "/app/app/app.py", line 41, in task_processing_themes_processing
    result = get_similar_tovar(req['text'])
KeyError: 'text'
[2020-02-01 19:19:28 +0000] [17] [ERROR] Error handling request /api/v1/themes/
Traceback (most recent call last):
  File "/usr/local/lib/python3.6/site-packages/gunicorn/workers/base_async.py", line 55, in handle
    self.handle_request(listener_name, req, client, addr)
  File "/usr/local/lib/python3.6/site-packages/gunicorn/workers/ggevent.py", line 143, in handle_request
    super().handle_request(listener_name, req, sock, addr)
  File "/usr/local/lib/python3.6/site-packages/gunicorn/workers/base_async.py", line 106, in handle_request
    respiter = self.wsgi(environ, resp.start_response)
  File "/usr/local/lib/python3.6/site-packages/flask/app.py", line 2309, in __call__
    return self.wsgi_app(environ, start_response)
  File "/usr/local/lib/python3.6/site-packages/flask/app.py", line 2295, in wsgi_app
    response = self.handle_exception(e)
  File "/usr/local/lib/python3.6/site-packages/flask_cors/extension.py", line 161, in wrapped_function
    return cors_after_request(app.make_response(f(*args, **kwargs)))
  File "/usr/local/lib/python3.6/site-packages/flask/app.py", line 1741, in handle_exception
    reraise(exc_type, exc_value, tb)
  File "/usr/local/lib/python3.6/site-packages/flask/_compat.py", line 35, in reraise
    raise value
  File "/usr/local/lib/python3.6/site-packages/flask/app.py", line 2292, in wsgi_app
    response = self.full_dispatch_request()
  File "/usr/local/lib/python3.6/site-packages/flask/app.py", line 1815, in full_dispatch_request
    rv = self.handle_user_exception(e)
  File "/usr/local/lib/python3.6/site-packages/flask_cors/extension.py", line 161, in wrapped_function
    return cors_after_request(app.make_response(f(*args, **kwargs)))
  File "/usr/local/lib/python3.6/site-packages/flask/app.py", line 1718, in handle_user_exception
    reraise(exc_type, exc_value, tb)
  File "/usr/local/lib/python3.6/site-packages/flask/_compat.py", line 35, in reraise
    raise value
  File "/usr/local/lib/python3.6/site-packages/flask/app.py", line 1813, in full_dispatch_request
    rv = self.dispatch_request()
  File "/usr/local/lib/python3.6/site-packages/flask/app.py", line 1799, in dispatch_request
    return self.view_functions[rule.endpoint](**req.view_args)
  File "/usr/local/lib/python3.6/site-packages/flask_cors/decorator.py", line 128, in wrapped_function
    resp = make_response(f(*args, **kwargs))
  File "/app/app/app.py", line 41, in task_processing_themes_processing
    result = get_similar_tovar(req['text'])
KeyError: 'text'
[2020-02-01 19:19:28 +0000] [18] [ERROR] Error handling request /api/v1/themes/
Traceback (most recent call last):
  File "/usr/local/lib/python3.6/site-packages/gunicorn/workers/base_async.py", line 55, in handle
    self.handle_request(listener_name, req, client, addr)
  File "/usr/local/lib/python3.6/site-packages/gunicorn/workers/ggevent.py", line 143, in handle_request
    super().handle_request(listener_name, req, sock, addr)
  File "/usr/local/lib/python3.6/site-packages/gunicorn/workers/base_async.py", line 106, in handle_request
    respiter = self.wsgi(environ, resp.start_response)
  File "/usr/local/lib/python3.6/site-packages/flask/app.py", line 2309, in __call__
    return self.wsgi_app(environ, start_response)
  File "/usr/local/lib/python3.6/site-packages/flask/app.py", line 2295, in wsgi_app
    response = self.handle_exception(e)
  File "/usr/local/lib/python3.6/site-packages/flask_cors/extension.py", line 161, in wrapped_function
    return cors_after_request(app.make_response(f(*args, **kwargs)))
  File "/usr/local/lib/python3.6/site-packages/flask/app.py", line 1741, in handle_exception
    reraise(exc_type, exc_value, tb)
  File "/usr/local/lib/python3.6/site-packages/flask/_compat.py", line 35, in reraise
    raise value
  File "/usr/local/lib/python3.6/site-packages/flask/app.py", line 2292, in wsgi_app
    response = self.full_dispatch_request()
  File "/usr/local/lib/python3.6/site-packages/flask/app.py", line 1815, in full_dispatch_request
    rv = self.handle_user_exception(e)
  File "/usr/local/lib/python3.6/site-packages/flask_cors/extension.py", line 161, in wrapped_function
    return cors_after_request(app.make_response(f(*args, **kwargs)))
  File "/usr/local/lib/python3.6/site-packages/flask/app.py", line 1718, in handle_user_exception
    reraise(exc_type, exc_value, tb)
  File "/usr/local/lib/python3.6/site-packages/flask/_compat.py", line 35, in reraise
    raise value
  File "/usr/local/lib/python3.6/site-packages/flask/app.py", line 1813, in full_dispatch_request
    rv = self.dispatch_request()
  File "/usr/local/lib/python3.6/site-packages/flask/app.py", line 1799, in dispatch_request
    return self.view_functions[rule.endpoint](**req.view_args)
  File "/usr/local/lib/python3.6/site-packages/flask_cors/decorator.py", line 128, in wrapped_function
    resp = make_response(f(*args, **kwargs))
  File "/app/app/app.py", line 41, in task_processing_themes_processing
    result = get_similar_tovar(req['text'])
KeyError: 'text'
[2020-02-01 19:19:28 +0000] [18] [ERROR] Error handling request /api/v1/themes/
Traceback (most recent call last):
  File "/usr/local/lib/python3.6/site-packages/gunicorn/workers/base_async.py", line 55, in handle
    self.handle_request(listener_name, req, client, addr)
  File "/usr/local/lib/python3.6/site-packages/gunicorn/workers/ggevent.py", line 143, in handle_request
    super().handle_request(listener_name, req, sock, addr)
  File "/usr/local/lib/python3.6/site-packages/gunicorn/workers/base_async.py", line 106, in handle_request
    respiter = self.wsgi(environ, resp.start_response)
  File "/usr/local/lib/python3.6/site-packages/flask/app.py", line 2309, in __call__
    return self.wsgi_app(environ, start_response)
  File "/usr/local/lib/python3.6/site-packages/flask/app.py", line 2295, in wsgi_app
    response = self.handle_exception(e)
  File "/usr/local/lib/python3.6/site-packages/flask_cors/extension.py", line 161, in wrapped_function
    return cors_after_request(app.make_response(f(*args, **kwargs)))
  File "/usr/local/lib/python3.6/site-packages/flask/app.py", line 1741, in handle_exception
    reraise(exc_type, exc_value, tb)
  File "/usr/local/lib/python3.6/site-packages/flask/_compat.py", line 35, in reraise
    raise value
  File "/usr/local/lib/python3.6/site-packages/flask/app.py", line 2292, in wsgi_app
    response = self.full_dispatch_request()
  File "/usr/local/lib/python3.6/site-packages/flask/app.py", line 1815, in full_dispatch_request
    rv = self.handle_user_exception(e)
  File "/usr/local/lib/python3.6/site-packages/flask_cors/extension.py", line 161, in wrapped_function
    return cors_after_request(app.make_response(f(*args, **kwargs)))
  File "/usr/local/lib/python3.6/site-packages/flask/app.py", line 1718, in handle_user_exception
    reraise(exc_type, exc_value, tb)
  File "/usr/local/lib/python3.6/site-packages/flask/_compat.py", line 35, in reraise
    raise value
  File "/usr/local/lib/python3.6/site-packages/flask/app.py", line 1813, in full_dispatch_request
    rv = self.dispatch_request()
  File "/usr/local/lib/python3.6/site-packages/flask/app.py", line 1799, in dispatch_request
    return self.view_functions[rule.endpoint](**req.view_args)
  File "/usr/local/lib/python3.6/site-packages/flask_cors/decorator.py", line 128, in wrapped_function
    resp = make_response(f(*args, **kwargs))
  File "/app/app/app.py", line 41, in task_processing_themes_processing
    result = get_similar_tovar(req['text'])
KeyError: 'text'
[2020-02-01 19:19:28 +0000] [18] [ERROR] Error handling request /api/v1/themes/
Traceback (most recent call last):
  File "/usr/local/lib/python3.6/site-packages/gunicorn/workers/base_async.py", line 55, in handle
    self.handle_request(listener_name, req, client, addr)
  File "/usr/local/lib/python3.6/site-packages/gunicorn/workers/ggevent.py", line 143, in handle_request
    super().handle_request(listener_name, req, sock, addr)
  File "/usr/local/lib/python3.6/site-packages/gunicorn/workers/base_async.py", line 106, in handle_request
    respiter = self.wsgi(environ, resp.start_response)
  File "/usr/local/lib/python3.6/site-packages/flask/app.py", line 2309, in __call__
    return self.wsgi_app(environ, start_response)
  File "/usr/local/lib/python3.6/site-packages/flask/app.py", line 2295, in wsgi_app
    response = self.handle_exception(e)
  File "/usr/local/lib/python3.6/site-packages/flask_cors/extension.py", line 161, in wrapped_function
    return cors_after_request(app.make_response(f(*args, **kwargs)))
  File "/usr/local/lib/python3.6/site-packages/flask/app.py", line 1741, in handle_exception
    reraise(exc_type, exc_value, tb)
  File "/usr/local/lib/python3.6/site-packages/flask/_compat.py", line 35, in reraise
    raise value
  File "/usr/local/lib/python3.6/site-packages/flask/app.py", line 2292, in wsgi_app
    response = self.full_dispatch_request()
  File "/usr/local/lib/python3.6/site-packages/flask/app.py", line 1815, in full_dispatch_request
    rv = self.handle_user_exception(e)
  File "/usr/local/lib/python3.6/site-packages/flask_cors/extension.py", line 161, in wrapped_function
    return cors_after_request(app.make_response(f(*args, **kwargs)))
  File "/usr/local/lib/python3.6/site-packages/flask/app.py", line 1718, in handle_user_exception
    reraise(exc_type, exc_value, tb)
  File "/usr/local/lib/python3.6/site-packages/flask/_compat.py", line 35, in reraise
    raise value
  File "/usr/local/lib/python3.6/site-packages/flask/app.py", line 1813, in full_dispatch_request
    rv = self.dispatch_request()
  File "/usr/local/lib/python3.6/site-packages/flask/app.py", line 1799, in dispatch_request
    return self.view_functions[rule.endpoint](**req.view_args)
  File "/usr/local/lib/python3.6/site-packages/flask_cors/decorator.py", line 128, in wrapped_function
    resp = make_response(f(*args, **kwargs))
  File "/app/app/app.py", line 41, in task_processing_themes_processing
    result = get_similar_tovar(req['text'])
KeyError: 'text'
[2020-02-01 19:19:28 +0000] [18] [ERROR] Error handling request /api/v1/themes/
Traceback (most recent call last):
  File "/usr/local/lib/python3.6/site-packages/gunicorn/workers/base_async.py", line 55, in handle
    self.handle_request(listener_name, req, client, addr)
  File "/usr/local/lib/python3.6/site-packages/gunicorn/workers/ggevent.py", line 143, in handle_request
    super().handle_request(listener_name, req, sock, addr)
  File "/usr/local/lib/python3.6/site-packages/gunicorn/workers/base_async.py", line 106, in handle_request
    respiter = self.wsgi(environ, resp.start_response)
  File "/usr/local/lib/python3.6/site-packages/flask/app.py", line 2309, in __call__
    return self.wsgi_app(environ, start_response)
  File "/usr/local/lib/python3.6/site-packages/flask/app.py", line 2295, in wsgi_app
    response = self.handle_exception(e)
  File "/usr/local/lib/python3.6/site-packages/flask_cors/extension.py", line 161, in wrapped_function
    return cors_after_request(app.make_response(f(*args, **kwargs)))
  File "/usr/local/lib/python3.6/site-packages/flask/app.py", line 1741, in handle_exception
    reraise(exc_type, exc_value, tb)
  File "/usr/local/lib/python3.6/site-packages/flask/_compat.py", line 35, in reraise
    raise value
  File "/usr/local/lib/python3.6/site-packages/flask/app.py", line 2292, in wsgi_app
    response = self.full_dispatch_request()
  File "/usr/local/lib/python3.6/site-packages/flask/app.py", line 1815, in full_dispatch_request
    rv = self.handle_user_exception(e)
  File "/usr/local/lib/python3.6/site-packages/flask_cors/extension.py", line 161, in wrapped_function
    return cors_after_request(app.make_response(f(*args, **kwargs)))
  File "/usr/local/lib/python3.6/site-packages/flask/app.py", line 1718, in handle_user_exception
    reraise(exc_type, exc_value, tb)
  File "/usr/local/lib/python3.6/site-packages/flask/_compat.py", line 35, in reraise
    raise value
  File "/usr/local/lib/python3.6/site-packages/flask/app.py", line 1813, in full_dispatch_request
    rv = self.dispatch_request()
  File "/usr/local/lib/python3.6/site-packages/flask/app.py", line 1799, in dispatch_request
    return self.view_functions[rule.endpoint](**req.view_args)
  File "/usr/local/lib/python3.6/site-packages/flask_cors/decorator.py", line 128, in wrapped_function
    resp = make_response(f(*args, **kwargs))
  File "/app/app/app.py", line 41, in task_processing_themes_processing
    result = get_similar_tovar(req['text'])
KeyError: 'text'
[2020-02-01 19:19:28 +0000] [16] [ERROR] Error handling request /api/v1/themes/
Traceback (most recent call last):
  File "/usr/local/lib/python3.6/site-packages/gunicorn/workers/base_async.py", line 55, in handle
    self.handle_request(listener_name, req, client, addr)
  File "/usr/local/lib/python3.6/site-packages/gunicorn/workers/ggevent.py", line 143, in handle_request
    super().handle_request(listener_name, req, sock, addr)
  File "/usr/local/lib/python3.6/site-packages/gunicorn/workers/base_async.py", line 106, in handle_request
    respiter = self.wsgi(environ, resp.start_response)
  File "/usr/local/lib/python3.6/site-packages/flask/app.py", line 2309, in __call__
    return self.wsgi_app(environ, start_response)
  File "/usr/local/lib/python3.6/site-packages/flask/app.py", line 2295, in wsgi_app
    response = self.handle_exception(e)
  File "/usr/local/lib/python3.6/site-packages/flask_cors/extension.py", line 161, in wrapped_function
    return cors_after_request(app.make_response(f(*args, **kwargs)))
  File "/usr/local/lib/python3.6/site-packages/flask/app.py", line 1741, in handle_exception
    reraise(exc_type, exc_value, tb)
  File "/usr/local/lib/python3.6/site-packages/flask/_compat.py", line 35, in reraise
    raise value
  File "/usr/local/lib/python3.6/site-packages/flask/app.py", line 2292, in wsgi_app
    response = self.full_dispatch_request()
  File "/usr/local/lib/python3.6/site-packages/flask/app.py", line 1815, in full_dispatch_request
    rv = self.handle_user_exception(e)
  File "/usr/local/lib/python3.6/site-packages/flask_cors/extension.py", line 161, in wrapped_function
    return cors_after_request(app.make_response(f(*args, **kwargs)))
  File "/usr/local/lib/python3.6/site-packages/flask/app.py", line 1718, in handle_user_exception
    reraise(exc_type, exc_value, tb)
  File "/usr/local/lib/python3.6/site-packages/flask/_compat.py", line 35, in reraise
    raise value
  File "/usr/local/lib/python3.6/site-packages/flask/app.py", line 1813, in full_dispatch_request
    rv = self.dispatch_request()
  File "/usr/local/lib/python3.6/site-packages/flask/app.py", line 1799, in dispatch_request
    return self.view_functions[rule.endpoint](**req.view_args)
  File "/usr/local/lib/python3.6/site-packages/flask_cors/decorator.py", line 128, in wrapped_function
    resp = make_response(f(*args, **kwargs))
  File "/app/app/app.py", line 41, in task_processing_themes_processing
    result = get_similar_tovar(req['text'])
KeyError: 'text'
[2020-02-01 19:19:28 +0000] [17] [ERROR] Error handling request /api/v1/themes/
Traceback (most recent call last):
  File "/usr/local/lib/python3.6/site-packages/gunicorn/workers/base_async.py", line 55, in handle
    self.handle_request(listener_name, req, client, addr)
  File "/usr/local/lib/python3.6/site-packages/gunicorn/workers/ggevent.py", line 143, in handle_request
    super().handle_request(listener_name, req, sock, addr)
  File "/usr/local/lib/python3.6/site-packages/gunicorn/workers/base_async.py", line 106, in handle_request
    respiter = self.wsgi(environ, resp.start_response)
  File "/usr/local/lib/python3.6/site-packages/flask/app.py", line 2309, in __call__
    return self.wsgi_app(environ, start_response)
  File "/usr/local/lib/python3.6/site-packages/flask/app.py", line 2295, in wsgi_app
    response = self.handle_exception(e)
  File "/usr/local/lib/python3.6/site-packages/flask_cors/extension.py", line 161, in wrapped_function
    return cors_after_request(app.make_response(f(*args, **kwargs)))
  File "/usr/local/lib/python3.6/site-packages/flask/app.py", line 1741, in handle_exception
    reraise(exc_type, exc_value, tb)
  File "/usr/local/lib/python3.6/site-packages/flask/_compat.py", line 35, in reraise
    raise value
  File "/usr/local/lib/python3.6/site-packages/flask/app.py", line 2292, in wsgi_app
    response = self.full_dispatch_request()
  File "/usr/local/lib/python3.6/site-packages/flask/app.py", line 1815, in full_dispatch_request
    rv = self.handle_user_exception(e)
  File "/usr/local/lib/python3.6/site-packages/flask_cors/extension.py", line 161, in wrapped_function
    return cors_after_request(app.make_response(f(*args, **kwargs)))
  File "/usr/local/lib/python3.6/site-packages/flask/app.py", line 1718, in handle_user_exception
    reraise(exc_type, exc_value, tb)
  File "/usr/local/lib/python3.6/site-packages/flask/_compat.py", line 35, in reraise
    raise value
  File "/usr/local/lib/python3.6/site-packages/flask/app.py", line 1813, in full_dispatch_request
    rv = self.dispatch_request()
  File "/usr/local/lib/python3.6/site-packages/flask/app.py", line 1799, in dispatch_request
    return self.view_functions[rule.endpoint](**req.view_args)
  File "/usr/local/lib/python3.6/site-packages/flask_cors/decorator.py", line 128, in wrapped_function
    resp = make_response(f(*args, **kwargs))
  File "/app/app/app.py", line 41, in task_processing_themes_processing
    result = get_similar_tovar(req['text'])
KeyError: 'text'
[2020-02-01 19:29:42 +0000] [16] [ERROR] Error handling request /api/v1/themes/
Traceback (most recent call last):
  File "/usr/local/lib/python3.6/site-packages/gunicorn/workers/base_async.py", line 55, in handle
    self.handle_request(listener_name, req, client, addr)
  File "/usr/local/lib/python3.6/site-packages/gunicorn/workers/ggevent.py", line 143, in handle_request
    super().handle_request(listener_name, req, sock, addr)
  File "/usr/local/lib/python3.6/site-packages/gunicorn/workers/base_async.py", line 106, in handle_request
    respiter = self.wsgi(environ, resp.start_response)
  File "/usr/local/lib/python3.6/site-packages/flask/app.py", line 2309, in __call__
    return self.wsgi_app(environ, start_response)
  File "/usr/local/lib/python3.6/site-packages/flask/app.py", line 2295, in wsgi_app
    response = self.handle_exception(e)
  File "/usr/local/lib/python3.6/site-packages/flask_cors/extension.py", line 161, in wrapped_function
    return cors_after_request(app.make_response(f(*args, **kwargs)))
  File "/usr/local/lib/python3.6/site-packages/flask/app.py", line 1741, in handle_exception
    reraise(exc_type, exc_value, tb)
  File "/usr/local/lib/python3.6/site-packages/flask/_compat.py", line 35, in reraise
    raise value
  File "/usr/local/lib/python3.6/site-packages/flask/app.py", line 2292, in wsgi_app
    response = self.full_dispatch_request()
  File "/usr/local/lib/python3.6/site-packages/flask/app.py", line 1815, in full_dispatch_request
    rv = self.handle_user_exception(e)
  File "/usr/local/lib/python3.6/site-packages/flask_cors/extension.py", line 161, in wrapped_function
    return cors_after_request(app.make_response(f(*args, **kwargs)))
  File "/usr/local/lib/python3.6/site-packages/flask/app.py", line 1718, in handle_user_exception
    reraise(exc_type, exc_value, tb)
  File "/usr/local/lib/python3.6/site-packages/flask/_compat.py", line 35, in reraise
    raise value
  File "/usr/local/lib/python3.6/site-packages/flask/app.py", line 1813, in full_dispatch_request
    rv = self.dispatch_request()
  File "/usr/local/lib/python3.6/site-packages/flask/app.py", line 1799, in dispatch_request
    return self.view_functions[rule.endpoint](**req.view_args)
  File "/usr/local/lib/python3.6/site-packages/flask_cors/decorator.py", line 128, in wrapped_function
    resp = make_response(f(*args, **kwargs))
  File "/app/app/app.py", line 41, in task_processing_themes_processing
    result = get_similar_tovar(req['text'])
KeyError: 'text'
[2020-02-01 19:52:43 +0000] [17] [INFO] Worker reloading: /app/app/speller.py modified
[2020-02-01 19:52:43 +0000] [18] [INFO] Worker reloading: /app/app/speller.py modified
[2020-02-01 19:52:43 +0000] [17] [INFO] Worker exiting (pid: 17)
[2020-02-01 19:52:43 +0000] [18] [INFO] Worker exiting (pid: 18)
[2020-02-01 19:52:44 +0000] [16] [INFO] Worker reloading: /app/app/speller.py modified
[2020-02-01 19:52:44 +0000] [16] [INFO] Worker exiting (pid: 16)
[2020-02-01 19:52:45 +0000] [20] [INFO] Booting worker with pid: 20
[2020-02-01 19:52:45 +0000] [21] [INFO] Booting worker with pid: 21
[2020-02-01 19:52:45 +0000] [22] [INFO] Booting worker with pid: 22
[2020-02-01 20:49:33 +0000] [22] [INFO] Worker reloading: /app/app/search.py modified
[2020-02-01 20:49:33 +0000] [22] [INFO] Worker exiting (pid: 22)
[2020-02-01 20:49:33 +0000] [20] [INFO] Worker reloading: /app/app/search.py modified
[2020-02-01 20:49:33 +0000] [20] [INFO] Worker exiting (pid: 20)
[2020-02-01 20:49:33 +0000] [21] [INFO] Worker reloading: /app/app/search.py modified
[2020-02-01 20:49:33 +0000] [21] [INFO] Worker exiting (pid: 21)
[2020-02-01 20:49:34 +0000] [23] [INFO] Booting worker with pid: 23
[2020-02-01 20:49:35 +0000] [24] [INFO] Booting worker with pid: 24
[2020-02-01 20:49:35 +0000] [25] [INFO] Booting worker with pid: 25
[2020-02-01 20:51:33 +0000] [23] [INFO] Worker reloading: /app/app/search.py modified
[2020-02-01 20:51:33 +0000] [23] [INFO] Worker exiting (pid: 23)
[2020-02-01 20:51:33 +0000] [24] [INFO] Worker reloading: /app/app/search.py modified
[2020-02-01 20:51:34 +0000] [25] [INFO] Worker reloading: /app/app/search.py modified
[2020-02-01 20:51:34 +0000] [25] [INFO] Worker exiting (pid: 25)
[2020-02-01 20:51:34 +0000] [26] [INFO] Booting worker with pid: 26
[2020-02-01 20:51:35 +0000] [27] [INFO] Booting worker with pid: 27
[2020-02-01 20:51:37 +0000] [24] [INFO] Worker exiting (pid: 24)
[2020-02-01 20:51:39 +0000] [28] [INFO] Booting worker with pid: 28
[2020-02-01 20:53:33 +0000] [28] [INFO] Worker reloading: /app/app/search.py modified
[2020-02-01 20:53:33 +0000] [28] [INFO] Worker exiting (pid: 28)
[2020-02-01 20:53:33 +0000] [26] [INFO] Worker reloading: /app/app/search.py modified
[2020-02-01 20:53:33 +0000] [26] [INFO] Worker exiting (pid: 26)
[2020-02-01 20:53:33 +0000] [27] [INFO] Worker reloading: /app/app/search.py modified
[2020-02-01 20:53:33 +0000] [27] [INFO] Worker exiting (pid: 27)
[2020-02-01 20:53:34 +0000] [29] [INFO] Booting worker with pid: 29
[2020-02-01 20:53:34 +0000] [30] [INFO] Booting worker with pid: 30
[2020-02-01 20:53:34 +0000] [31] [INFO] Booting worker with pid: 31
[2020-02-01 20:54:13 +0000] [29] [INFO] Worker reloading: /app/app/search.py modified
[2020-02-01 20:54:13 +0000] [29] [INFO] Worker exiting (pid: 29)
[2020-02-01 20:54:13 +0000] [30] [INFO] Worker reloading: /app/app/search.py modified
[2020-02-01 20:54:13 +0000] [31] [INFO] Worker reloading: /app/app/search.py modified
[2020-02-01 20:54:13 +0000] [30] [INFO] Worker exiting (pid: 30)
[2020-02-01 20:54:13 +0000] [31] [INFO] Worker exiting (pid: 31)
[2020-02-01 20:54:14 +0000] [32] [INFO] Booting worker with pid: 32
[2020-02-01 20:54:14 +0000] [33] [INFO] Booting worker with pid: 33
[2020-02-01 20:54:14 +0000] [34] [INFO] Booting worker with pid: 34
[2020-02-01 20:54:44 +0000] [32] [INFO] Worker reloading: /app/app/search.py modified
[2020-02-01 20:54:44 +0000] [32] [INFO] Worker exiting (pid: 32)
[2020-02-01 20:54:44 +0000] [33] [INFO] Worker reloading: /app/app/search.py modified
[2020-02-01 20:54:44 +0000] [33] [INFO] Worker exiting (pid: 33)
[2020-02-01 20:54:44 +0000] [34] [INFO] Worker reloading: /app/app/search.py modified
[2020-02-01 20:54:44 +0000] [34] [INFO] Worker exiting (pid: 34)
[2020-02-01 20:54:45 +0000] [35] [INFO] Booting worker with pid: 35
[2020-02-01 20:54:45 +0000] [36] [INFO] Booting worker with pid: 36
[2020-02-01 20:54:46 +0000] [37] [INFO] Booting worker with pid: 37
[2020-02-01 20:56:17 +0000] [35] [INFO] Worker reloading: /app/app/app.py modified
[2020-02-01 20:56:17 +0000] [35] [INFO] Worker exiting (pid: 35)
[2020-02-01 20:56:17 +0000] [36] [INFO] Worker reloading: /app/app/app.py modified
[2020-02-01 20:56:17 +0000] [36] [INFO] Worker exiting (pid: 36)
[2020-02-01 20:56:17 +0000] [37] [INFO] Worker reloading: /app/app/app.py modified
[2020-02-01 20:56:17 +0000] [37] [INFO] Worker exiting (pid: 37)
[2020-02-01 20:56:18 +0000] [38] [INFO] Booting worker with pid: 38
[2020-02-01 20:56:18 +0000] [39] [INFO] Booting worker with pid: 39
[2020-02-01 20:56:18 +0000] [40] [INFO] Booting worker with pid: 40
[2020-02-01 20:58:08 +0000] [39] [INFO] Worker reloading: /app/app/app.py modified
[2020-02-01 20:58:08 +0000] [39] [INFO] Worker exiting (pid: 39)
[2020-02-01 20:58:08 +0000] [40] [INFO] Worker reloading: /app/app/app.py modified
[2020-02-01 20:58:08 +0000] [40] [INFO] Worker exiting (pid: 40)
[2020-02-01 20:58:08 +0000] [38] [INFO] Worker reloading: /app/app/app.py modified
[2020-02-01 20:58:08 +0000] [38] [INFO] Worker exiting (pid: 38)
[2020-02-01 20:58:09 +0000] [41] [INFO] Booting worker with pid: 41
[2020-02-01 20:58:09 +0000] [42] [INFO] Booting worker with pid: 42
[2020-02-01 20:58:09 +0000] [43] [INFO] Booting worker with pid: 43
[2020-02-01 21:01:55 +0000] [9] [INFO] Starting gunicorn 20.0.4
[2020-02-01 21:01:55 +0000] [9] [INFO] Listening at: http://0.0.0.0:7777 (9)
[2020-02-01 21:01:55 +0000] [9] [INFO] Using worker: gevent
[2020-02-01 21:01:55 +0000] [16] [INFO] Booting worker with pid: 16
[2020-02-01 21:01:55 +0000] [17] [INFO] Booting worker with pid: 17
[2020-02-01 21:01:56 +0000] [18] [INFO] Booting worker with pid: 18
[2020-02-01 21:03:56 +0000] [16] [ERROR] Error handling request /api/v1/themes/
Traceback (most recent call last):
  File "/usr/local/lib/python3.6/site-packages/gunicorn/workers/base_async.py", line 55, in handle
    self.handle_request(listener_name, req, client, addr)
  File "/usr/local/lib/python3.6/site-packages/gunicorn/workers/ggevent.py", line 143, in handle_request
    super().handle_request(listener_name, req, sock, addr)
  File "/usr/local/lib/python3.6/site-packages/gunicorn/workers/base_async.py", line 106, in handle_request
    respiter = self.wsgi(environ, resp.start_response)
  File "/usr/local/lib/python3.6/site-packages/flask/app.py", line 2309, in __call__
    return self.wsgi_app(environ, start_response)
  File "/usr/local/lib/python3.6/site-packages/flask/app.py", line 2295, in wsgi_app
    response = self.handle_exception(e)
  File "/usr/local/lib/python3.6/site-packages/flask_cors/extension.py", line 161, in wrapped_function
    return cors_after_request(app.make_response(f(*args, **kwargs)))
  File "/usr/local/lib/python3.6/site-packages/flask/app.py", line 1741, in handle_exception
    reraise(exc_type, exc_value, tb)
  File "/usr/local/lib/python3.6/site-packages/flask/_compat.py", line 35, in reraise
    raise value
  File "/usr/local/lib/python3.6/site-packages/flask/app.py", line 2292, in wsgi_app
    response = self.full_dispatch_request()
  File "/usr/local/lib/python3.6/site-packages/flask/app.py", line 1815, in full_dispatch_request
    rv = self.handle_user_exception(e)
  File "/usr/local/lib/python3.6/site-packages/flask_cors/extension.py", line 161, in wrapped_function
    return cors_after_request(app.make_response(f(*args, **kwargs)))
  File "/usr/local/lib/python3.6/site-packages/flask/app.py", line 1718, in handle_user_exception
    reraise(exc_type, exc_value, tb)
  File "/usr/local/lib/python3.6/site-packages/flask/_compat.py", line 35, in reraise
    raise value
  File "/usr/local/lib/python3.6/site-packages/flask/app.py", line 1813, in full_dispatch_request
    rv = self.dispatch_request()
  File "/usr/local/lib/python3.6/site-packages/flask/app.py", line 1799, in dispatch_request
    return self.view_functions[rule.endpoint](**req.view_args)
  File "/usr/local/lib/python3.6/site-packages/flask_cors/decorator.py", line 128, in wrapped_function
    resp = make_response(f(*args, **kwargs))
  File "/app/app/app.py", line 52, in task_processing_themes_processing
    result = get_similar_tovar(class_p=class_p, class_t=class_t, text = get_text)
  File "/app/app/search.py", line 107, in get_similar_tovar
    similar_tovar_id = filters(class_p=class_p, class_t=class_t, table = similar_tovar_id)
  File "/app/app/search.py", line 137, in filters
    table = table[table['Вид товаров'].isin([class_t])]
TypeError: list indices must be integers or slices, not str
[2020-02-01 21:37:50 +0000] [16] [INFO] Worker reloading: /app/app/search.py modified
[2020-02-01 21:37:50 +0000] [16] [INFO] Worker exiting (pid: 16)
[2020-02-01 21:37:51 +0000] [18] [INFO] Worker reloading: /app/app/search.py modified
[2020-02-01 21:37:51 +0000] [18] [INFO] Worker exiting (pid: 18)
[2020-02-01 21:37:51 +0000] [17] [INFO] Worker reloading: /app/app/search.py modified
[2020-02-01 21:37:51 +0000] [17] [INFO] Worker exiting (pid: 17)
[2020-02-01 21:37:51 +0000] [19] [INFO] Booting worker with pid: 19
[2020-02-01 21:37:52 +0000] [20] [INFO] Booting worker with pid: 20
[2020-02-01 21:37:52 +0000] [21] [INFO] Booting worker with pid: 21
[2020-02-01 21:39:06 +0000] [8] [INFO] Starting gunicorn 20.0.4
[2020-02-01 21:39:06 +0000] [8] [INFO] Listening at: http://0.0.0.0:7777 (8)
[2020-02-01 21:39:06 +0000] [8] [INFO] Using worker: gevent
[2020-02-01 21:39:06 +0000] [15] [INFO] Booting worker with pid: 15
[2020-02-01 21:39:07 +0000] [16] [INFO] Booting worker with pid: 16
[2020-02-01 21:39:07 +0000] [17] [INFO] Booting worker with pid: 17
[2020-02-01 22:49:59 +0000] [17] [ERROR] Error handling request /api/v1/themes/
Traceback (most recent call last):
  File "/usr/local/lib/python3.6/site-packages/gunicorn/workers/base_async.py", line 55, in handle
    self.handle_request(listener_name, req, client, addr)
  File "/usr/local/lib/python3.6/site-packages/gunicorn/workers/ggevent.py", line 143, in handle_request
    super().handle_request(listener_name, req, sock, addr)
  File "/usr/local/lib/python3.6/site-packages/gunicorn/workers/base_async.py", line 106, in handle_request
    respiter = self.wsgi(environ, resp.start_response)
  File "/usr/local/lib/python3.6/site-packages/flask/app.py", line 2309, in __call__
    return self.wsgi_app(environ, start_response)
  File "/usr/local/lib/python3.6/site-packages/flask/app.py", line 2295, in wsgi_app
    response = self.handle_exception(e)
  File "/usr/local/lib/python3.6/site-packages/flask_cors/extension.py", line 161, in wrapped_function
    return cors_after_request(app.make_response(f(*args, **kwargs)))
  File "/usr/local/lib/python3.6/site-packages/flask/app.py", line 1741, in handle_exception
    reraise(exc_type, exc_value, tb)
  File "/usr/local/lib/python3.6/site-packages/flask/_compat.py", line 35, in reraise
    raise value
  File "/usr/local/lib/python3.6/site-packages/flask/app.py", line 2292, in wsgi_app
    response = self.full_dispatch_request()
  File "/usr/local/lib/python3.6/site-packages/flask/app.py", line 1815, in full_dispatch_request
    rv = self.handle_user_exception(e)
  File "/usr/local/lib/python3.6/site-packages/flask_cors/extension.py", line 161, in wrapped_function
    return cors_after_request(app.make_response(f(*args, **kwargs)))
  File "/usr/local/lib/python3.6/site-packages/flask/app.py", line 1718, in handle_user_exception
    reraise(exc_type, exc_value, tb)
  File "/usr/local/lib/python3.6/site-packages/flask/_compat.py", line 35, in reraise
    raise value
  File "/usr/local/lib/python3.6/site-packages/flask/app.py", line 1813, in full_dispatch_request
    rv = self.dispatch_request()
  File "/usr/local/lib/python3.6/site-packages/flask/app.py", line 1799, in dispatch_request
    return self.view_functions[rule.endpoint](**req.view_args)
  File "/usr/local/lib/python3.6/site-packages/flask_cors/decorator.py", line 128, in wrapped_function
    resp = make_response(f(*args, **kwargs))
  File "/app/app/app.py", line 52, in task_processing_themes_processing
    result = get_similar_tovar(class_p=class_p, class_t=class_t, text = get_text)
  File "/app/app/search.py", line 128, in get_similar_tovar
    similar_tovar = filters(class_p=class_p, class_t=class_t, similar_tovar = similar_tovar)
  File "/app/app/search.py", line 152, in filters
    table = pd.DataFrame(pd.Series(similar_tovar[0])).T
IndexError: list index out of range
[2020-02-01 23:00:46 +0000] [15] [ERROR] Error handling request /api/v1/themes/
Traceback (most recent call last):
  File "/usr/local/lib/python3.6/site-packages/gunicorn/workers/base_async.py", line 55, in handle
    self.handle_request(listener_name, req, client, addr)
  File "/usr/local/lib/python3.6/site-packages/gunicorn/workers/ggevent.py", line 143, in handle_request
    super().handle_request(listener_name, req, sock, addr)
  File "/usr/local/lib/python3.6/site-packages/gunicorn/workers/base_async.py", line 106, in handle_request
    respiter = self.wsgi(environ, resp.start_response)
  File "/usr/local/lib/python3.6/site-packages/flask/app.py", line 2309, in __call__
    return self.wsgi_app(environ, start_response)
  File "/usr/local/lib/python3.6/site-packages/flask/app.py", line 2295, in wsgi_app
    response = self.handle_exception(e)
  File "/usr/local/lib/python3.6/site-packages/flask_cors/extension.py", line 161, in wrapped_function
    return cors_after_request(app.make_response(f(*args, **kwargs)))
  File "/usr/local/lib/python3.6/site-packages/flask/app.py", line 1741, in handle_exception
    reraise(exc_type, exc_value, tb)
  File "/usr/local/lib/python3.6/site-packages/flask/_compat.py", line 35, in reraise
    raise value
  File "/usr/local/lib/python3.6/site-packages/flask/app.py", line 2292, in wsgi_app
    response = self.full_dispatch_request()
  File "/usr/local/lib/python3.6/site-packages/flask/app.py", line 1815, in full_dispatch_request
    rv = self.handle_user_exception(e)
  File "/usr/local/lib/python3.6/site-packages/flask_cors/extension.py", line 161, in wrapped_function
    return cors_after_request(app.make_response(f(*args, **kwargs)))
  File "/usr/local/lib/python3.6/site-packages/flask/app.py", line 1718, in handle_user_exception
    reraise(exc_type, exc_value, tb)
  File "/usr/local/lib/python3.6/site-packages/flask/_compat.py", line 35, in reraise
    raise value
  File "/usr/local/lib/python3.6/site-packages/flask/app.py", line 1813, in full_dispatch_request
    rv = self.dispatch_request()
  File "/usr/local/lib/python3.6/site-packages/flask/app.py", line 1799, in dispatch_request
    return self.view_functions[rule.endpoint](**req.view_args)
  File "/usr/local/lib/python3.6/site-packages/flask_cors/decorator.py", line 128, in wrapped_function
    resp = make_response(f(*args, **kwargs))
  File "/app/app/app.py", line 52, in task_processing_themes_processing
    result = get_similar_tovar(class_p=class_p, class_t=class_t, text = get_text)
  File "/app/app/search.py", line 128, in get_similar_tovar
    similar_tovar = filters(class_p=class_p, class_t=class_t, similar_tovar = similar_tovar)
  File "/app/app/search.py", line 152, in filters
    table = pd.DataFrame(pd.Series(similar_tovar[0])).T
IndexError: list index out of range
[2020-02-01 23:44:52 +0000] [16] [INFO] Worker reloading: /app/app/search.py modified
[2020-02-01 23:44:52 +0000] [16] [INFO] Worker exiting (pid: 16)
[2020-02-01 23:44:52 +0000] [17] [INFO] Worker reloading: /app/app/search.py modified
[2020-02-01 23:44:52 +0000] [17] [INFO] Worker exiting (pid: 17)
[2020-02-01 23:44:53 +0000] [15] [INFO] Worker reloading: /app/app/search.py modified
[2020-02-01 23:44:53 +0000] [15] [INFO] Worker exiting (pid: 15)
[2020-02-01 23:44:53 +0000] [18] [INFO] Booting worker with pid: 18
[2020-02-01 23:44:54 +0000] [19] [INFO] Booting worker with pid: 19
[2020-02-01 23:44:54 +0000] [20] [INFO] Booting worker with pid: 20
[2020-02-01 23:46:16 +0000] [20] [INFO] Worker reloading: /app/app/search.py modified
[2020-02-01 23:46:16 +0000] [20] [INFO] Worker exiting (pid: 20)
[2020-02-01 23:46:16 +0000] [18] [INFO] Worker reloading: /app/app/search.py modified
[2020-02-01 23:46:16 +0000] [18] [INFO] Worker exiting (pid: 18)
[2020-02-01 23:46:16 +0000] [19] [INFO] Worker reloading: /app/app/search.py modified
[2020-02-01 23:46:16 +0000] [19] [INFO] Worker exiting (pid: 19)
[2020-02-01 23:46:17 +0000] [21] [INFO] Booting worker with pid: 21
[2020-02-01 23:46:17 +0000] [22] [INFO] Booting worker with pid: 22
[2020-02-01 23:46:17 +0000] [23] [INFO] Booting worker with pid: 23
[2020-02-01 23:46:29 +0000] [21] [INFO] Worker reloading: /app/app/app.py modified
[2020-02-01 23:46:29 +0000] [21] [INFO] Worker exiting (pid: 21)
[2020-02-01 23:46:29 +0000] [22] [INFO] Worker reloading: /app/app/app.py modified
[2020-02-01 23:46:29 +0000] [22] [INFO] Worker exiting (pid: 22)
[2020-02-01 23:46:30 +0000] [23] [INFO] Worker reloading: /app/app/app.py modified
[2020-02-01 23:46:30 +0000] [23] [INFO] Worker exiting (pid: 23)
[2020-02-01 23:46:30 +0000] [24] [INFO] Booting worker with pid: 24
[2020-02-01 23:46:31 +0000] [25] [INFO] Booting worker with pid: 25
[2020-02-01 23:46:31 +0000] [26] [INFO] Booting worker with pid: 26
[2020-02-01 23:47:34 +0000] [24] [INFO] Worker reloading: /app/app/app.py modified
[2020-02-01 23:47:34 +0000] [25] [INFO] Worker reloading: /app/app/app.py modified
[2020-02-01 23:47:34 +0000] [24] [INFO] Worker exiting (pid: 24)
[2020-02-01 23:47:34 +0000] [25] [INFO] Worker exiting (pid: 25)
[2020-02-01 23:47:34 +0000] [26] [INFO] Worker reloading: /app/app/app.py modified
[2020-02-01 23:47:34 +0000] [26] [INFO] Worker exiting (pid: 26)
[2020-02-01 23:47:35 +0000] [27] [INFO] Booting worker with pid: 27
[2020-02-01 23:47:35 +0000] [29] [INFO] Booting worker with pid: 29
[2020-02-01 23:47:35 +0000] [30] [INFO] Booting worker with pid: 30
[2020-02-01 23:53:12 +0000] [11] [INFO] Starting gunicorn 20.0.4
[2020-02-01 23:53:12 +0000] [11] [INFO] Listening at: http://0.0.0.0:7777 (11)
[2020-02-01 23:53:12 +0000] [11] [INFO] Using worker: gevent
[2020-02-01 23:53:12 +0000] [18] [INFO] Booting worker with pid: 18
[2020-02-01 23:53:12 +0000] [19] [INFO] Booting worker with pid: 19
[2020-02-01 23:53:12 +0000] [20] [INFO] Booting worker with pid: 20
